Workbook
Name budget2024: 'FFB Budget 2024'!$C$5:$U$57
Name coupe: 'FFB Budget 2024'!#REF!
Name coupe: 'FFB Budget 2025'!$W$5:$Z$55
Name DARSO: 'DARSO GANG'!$A$7:$BH$14
Name ERDI: 'YUDI GANG'!$A$7:$BH$9
Name fbticket: '[1]FFB TICKET(DAY BY DAY) (2)'!$G$6:$R$303+'FFB Budget 2024'!$C$5:$U$56
Name fbticket: '[1]FFB TICKET(DAY BY DAY) (2)'!$G$6:$R$303+'FFB Budget 2025'!$C$5:$U$56
Name ffbbudgettwofive: 'FFB Budget 2024'!$C$5:$U$100
Name ffbbudgettwofive: 'FFB Budget 2025'!$C$5:$U$100
Name harvestinground: 'HARVESTING ROUND'!$B$3:$J$36
Name ironhorsediesel: '[1]REPORT DIESEL'!$B$97:$AO$119
Name july: 'HARVESTING ROUND'!$N$3:$Y$37
Name machinestatus: '[1]DAILY MACHINE REPORT'!$B$76:$AQ$97
Name manday: 'HARVESTING INTERVAL- Dec'!$C$5:$BG$76
Name NURAZANI: 'NU AZANI GANG'!$A$7:$BH$12
Name october2024: 'HARVESTING INTERVAL- NOV 24'!$C$5:$BG$76
Name SERAN: 'SOFIO GANG'!$A$7:$BH$12
Name WENDERLINUS: 'WENDERLINUS GANG '!$A$7:$BH$14
Name year2022to23: '4.4 Harvesting Round Record'!$B$9:$XFD$50
Name YUVENTUS: 'YUVENTUS UN GANG'!$A$7:$BH$9
Name yuventus2: '[3]YUVENTUS UN GANG'!$A$7:$BH$9

Sheet OVERALL BY GANG COMPARISON V3
A1: HARVESTER PERFORMANCE COMPARISON FOR CURRENT MONTH VS. PREVIOUS MONTH & VS PAST YEAR'S MONTH
A2: 45992
D3: 2025
D4: FFB PRODUCTION OF THE MONTH | H4: Budget 2025 (MT) | I4: MT / HA OF THE MONTH | K4: YTD | M4: YTD MT / HA
A5: Gang | C5: Total HA | D5: 1st Round (MT) | E5: 2nd Round (MT) | F5: 3rd Round (MT) | G5: Actual Total (MT) | I5: Actual | J5: Budget 2025 | K5: Actual | L5: Budget 2025 | M5: Actual | N5: Budget 2025 | AD5: 2025 FFB BUDGET
A6: YUVENTUS UN GANG | C6: ='YUVENTUS UN GANG'!B10 -> 164 | D6: ='YUVENTUS UN GANG'!D10 -> 106.52 | E6: ='YUVENTUS UN GANG'!E10 -> 125.98 | F6: ='YUVENTUS UN GANG'!F10 -> 0 | G6: =SUM(D6:F6) -> 232.5 | H6: ='YUVENTUS UN GANG'!C10 -> 331 | I6: =G6/C6 -> 1.4176829 | J6: =H6/C6 -> 2.0182927 | K6: =SUM(K7:K9) -> 2709.57 | L6: =ROUND(SUM(L7:L9),0) -> 3318 | M6: =K6/C6 -> 16.521768 | N6: =L6/C6 -> 20.231707 | AD6: Jan | AE6: Feb | AF6: Mar | AG6: Apr | AH6: May | AI6: Jun | AJ6: Jul | AK6: Aug | AL6: Sep | AM6: Oct | AN6: Nov | AO6: Dec
B7: 1 | C7: =VLOOKUP(B7,YUVENTUS,2,FALSE) -> 53.2 | D7: =VLOOKUP(B7,YUVENTUS,4,FALSE) -> 45.47 | E7: =VLOOKUP(B7,YUVENTUS,5,FALSE) -> 61.18 | F7: =VLOOKUP(B7,YUVENTUS,6,FALSE) -> 0 | G7: =SUM(D7:F7) -> 106.65 | H7: =VLOOKUP(B7,YUVENTUS,3,FALSE) -> 106 | I7: =G7/C7 -> 2.0046992 | J7: =H7/C7 -> 1.9924812 | K7: =VLOOKUP(B7,year2022to23,311,FALSE) -> 909.79 | L7: =SUM(AD7:AO7) -> 1062.68 | M7: =K7/C7 -> 17.101316 | N7: =L7/C7 -> 19.975188 | AD7: =VLOOKUP(B7,ffbbudgettwofive,7,FALSE) -> 53.2 | AE7: =VLOOKUP(B7,ffbbudgettwofive,8,FALSE) -> 42.56 | AF7: =VLOOKUP(B7,ffbbudgettwofive,9,FALSE) -> 74.48 | AG7: =VLOOKUP(B7,ffbbudgettwofive,10,FALSE) -> 74.48 | AH7: =VLOOKUP(B7,ffbbudgettwofive,11,FALSE) -> 74.48 | AI7: =VLOOKUP(B7,ffbbudgettwofive,12,FALSE) -> 74.48 | AJ7: =VLOOKUP(B7,ffbbudgettwofive,13,FALSE) -> 85 | AK7: =VLOOKUP(B7,ffbbudgettwofive,14,FALSE) -> 106 | AL7: =VLOOKUP(B7,ffbbudgettwofive,15,FALSE) -> 106 | AM7: =VLOOKUP(B7,ffbbudgettwofive,16,FALSE) -> 149 | AN7: =VLOOKUP(B7,ffbbudgettwofive,17,FALSE) -> 117 | AO7: =VLOOKUP(B7,ffbbudgettwofive,18,FALSE) -> 106
B8: 3 | C8: =VLOOKUP(B8,YUVENTUS,2,FALSE) -> 69.2 | D8: =VLOOKUP(B8,YUVENTUS,4,FALSE) -> 15.21 | E8: =VLOOKUP(B8,YUVENTUS,5,FALSE) -> 64.8 | F8: =VLOOKUP(B8,YUVENTUS,6,FALSE) -> 0 | G8: =SUM(D8:F8) -> 80.01 | H8: =VLOOKUP(B8,YUVENTUS,3,FALSE) -> 138 | I8: =G8/C8 -> 1.1562139 | J8: =H8/C8 -> 1.9942197 | K8: =VLOOKUP(B8,year2022to23,311,FALSE) -> 1085.75 | L8: =SUM(AD8:AO8) -> 1383.08 | M8: =K8/C8 -> 15.690029 | N8: =L8/C8 -> 19.986705 | AD8: =VLOOKUP(B8,ffbbudgettwofive,7,FALSE) -> 69.2 | AE8: =VLOOKUP(B8,ffbbudgettwofive,8,FALSE) -> 55.36 | AF8: =VLOOKUP(B8,ffbbudgettwofive,9,FALSE) -> 96.88 | AG8: =VLOOKUP(B8,ffbbudgettwofive,10,FALSE) -> 96.88 | AH8: =VLOOKUP(B8,ffbbudgettwofive,11,FALSE) -> 96.88 | AI8: =VLOOKUP(B8,ffbbudgettwofive,12,FALSE) -> 96.88 | AJ8: =VLOOKUP(B8,ffbbudgettwofive,13,FALSE) -> 111 | AK8: =VLOOKUP(B8,ffbbudgettwofive,14,FALSE) -> 138 | AL8: =VLOOKUP(B8,ffbbudgettwofive,15,FALSE) -> 138 | AM8: =VLOOKUP(B8,ffbbudgettwofive,16,FALSE) -> 194 | AN8: =VLOOKUP(B8,ffbbudgettwofive,17,FALSE) -> 152 | AO8: =VLOOKUP(B8,ffbbudgettwofive,18,FALSE) -> 138
B9: 14 | C9: =VLOOKUP(B9,YUVENTUS,2,FALSE) -> 41.6 | D9: =VLOOKUP(B9,YUVENTUS,4,FALSE) -> 45.84 | E9: =VLOOKUP(B9,YUVENTUS,5,FALSE) -> 0 | F9: =VLOOKUP(B9,YUVENTUS,6,FALSE) -> 0 | G9: =SUM(D9:F9) -> 45.84 | H9: =VLOOKUP(B9,YUVENTUS,3,FALSE) -> 87 | I9: =G9/C9 -> 1.1019231 | J9: =H9/C9 -> 2.0913462 | K9: =VLOOKUP(B9,year2022to23,311,FALSE) -> 714.03 | L9: =SUM(AD9:AO9) -> 872.38 | M9: =K9/C9 -> 17.164183 | N9: =L9/C9 -> 20.970673 | AD9: =VLOOKUP(B9,ffbbudgettwofive,7,FALSE) -> 43.7 | AE9: =VLOOKUP(B9,ffbbudgettwofive,8,FALSE) -> 34.96 | AF9: =VLOOKUP(B9,ffbbudgettwofive,9,FALSE) -> 61.18 | AG9: =VLOOKUP(B9,ffbbudgettwofive,10,FALSE) -> 61.18 | AH9: =VLOOKUP(B9,ffbbudgettwofive,11,FALSE) -> 61.18 | AI9: =VLOOKUP(B9,ffbbudgettwofive,12,FALSE) -> 61.18 | AJ9: =VLOOKUP(B9,ffbbudgettwofive,13,FALSE) -> 70 | AK9: =VLOOKUP(B9,ffbbudgettwofive,14,FALSE) -> 87 | AL9: =VLOOKUP(B9,ffbbudgettwofive,15,FALSE) -> 87 | AM9: =VLOOKUP(B9,ffbbudgettwofive,16,FALSE) -> 122 | AN9: =VLOOKUP(B9,ffbbudgettwofive,17,FALSE) -> 96 | AO9: =VLOOKUP(B9,ffbbudgettwofive,18,FALSE) -> 87
A11: DARSO GANG | C11: ='DARSO GANG'!B14 -> 385.4 | D11: ='DARSO GANG'!D14 -> 473.61 | E11: ='DARSO GANG'!E14 -> 218.56 | F11: ='DARSO GANG'!F14 -> 0 | G11: =SUM(D11:F11) -> 692.17 | H11: ='DARSO GANG'!C14 -> 818 | I11: =G11/C11 -> 1.7959782 | J11: =H11/C11 -> 2.1224702 | K11: =SUM(K12:K18) -> 6539.67 | L11: =ROUND(SUM(L12:L18),0) -> 8181 | M11: =K11/C11 -> 16.968526 | N11: =L11/C11 -> 21.227296 | AD11: Jan | AE11: Feb | AF11: Mar | AG11: Apr | AH11: May | AI11: Jun | AJ11: Jul | AK11: Aug | AL11: Sep | AM11: Oct | AN11: Nov | AO11: Dec
B12: 15 | C12: =VLOOKUP(B12,DARSO,2,FALSE) -> 49.3 | D12: =VLOOKUP(B12,DARSO,4,FALSE) -> 70.9 | E12: =VLOOKUP(B12,DARSO,5,FALSE) -> 53.16 | F12: =VLOOKUP(B12,DARSO,6,FALSE) -> 0 | G12: =SUM(D12:F12) -> 124.06 | H12: =VLOOKUP(B12,DARSO,3,FALSE) -> 99 | I12: =G12/C12 -> 2.51643 | J12: =H12/C12 -> 2.0081136 | K12: =VLOOKUP(B12,year2022to23,311,FALSE) -> 776.89 | L12: =SUM(AD12:AO12) -> 986.82 | M12: =K12/C12 -> 15.758418 | N12: =L12/C12 -> 20.016633 | AD12: =VLOOKUP(B12,ffbbudgettwofive,7,FALSE) -> 49.3 | AE12: =VLOOKUP(B12,ffbbudgettwofive,8,FALSE) -> 39.44 | AF12: =VLOOKUP(B12,ffbbudgettwofive,9,FALSE) -> 69.02 | AG12: =VLOOKUP(B12,ffbbudgettwofive,10,FALSE) -> 69.02 | AH12: =VLOOKUP(B12,ffbbudgettwofive,11,FALSE) -> 69.02 | AI12: =VLOOKUP(B12,ffbbudgettwofive,12,FALSE) -> 69.02 | AJ12: =VLOOKUP(B12,ffbbudgettwofive,13,FALSE) -> 79 | AK12: =VLOOKUP(B12,ffbbudgettwofive,14,FALSE) -> 99 | AL12: =VLOOKUP(B12,ffbbudgettwofive,15,FALSE) -> 99 | AM12: =VLOOKUP(B12,ffbbudgettwofive,16,FALSE) -> 138 | AN12: =VLOOKUP(B12,ffbbudgettwofive,17,FALSE) -> 108 | AO12: =VLOOKUP(B12,ffbbudgettwofive,18,FALSE) -> 99
B13: 16 | C13: =VLOOKUP(B13,DARSO,2,FALSE) -> 53.2 | D13: =VLOOKUP(B13,DARSO,4,FALSE) -> 53.38 | E13: =VLOOKUP(B13,DARSO,5,FALSE) -> 58.28 | F13: =VLOOKUP(B13,DARSO,6,FALSE) -> 0 | G13: =SUM(D13:F13) -> 111.66 | H13: =VLOOKUP(B13,DARSO,3,FALSE) -> 106 | I13: =G13/C13 -> 2.0988722 | J13: =H13/C13 -> 1.9924812 | K13: =VLOOKUP(B13,year2022to23,311,FALSE) -> 900.68 | L13: =SUM(AD13:AO13) -> 1062.68 | M13: =K13/C13 -> 16.930075 | N13: =L13/C13 -> 19.975188 | AD13: =VLOOKUP(B13,ffbbudgettwofive,7,FALSE) -> 53.2 | AE13: =VLOOKUP(B13,ffbbudgettwofive,8,FALSE) -> 42.56 | AF13: =VLOOKUP(B13,ffbbudgettwofive,9,FALSE) -> 74.48 | AG13: =VLOOKUP(B13,ffbbudgettwofive,10,FALSE) -> 74.48 | AH13: =VLOOKUP(B13,ffbbudgettwofive,11,FALSE) -> 74.48 | AI13: =VLOOKUP(B13,ffbbudgettwofive,12,FALSE) -> 74.48 | AJ13: =VLOOKUP(B13,ffbbudgettwofive,13,FALSE) -> 85 | AK13: =VLOOKUP(B13,ffbbudgettwofive,14,FALSE) -> 106 | AL13: =VLOOKUP(B13,ffbbudgettwofive,15,FALSE) -> 106 | AM13: =VLOOKUP(B13,ffbbudgettwofive,16,FALSE) -> 149 | AN13: =VLOOKUP(B13,ffbbudgettwofive,17,FALSE) -> 117 | AO13: =VLOOKUP(B13,ffbbudgettwofive,18,FALSE) -> 106
B14: 17 | C14: =VLOOKUP(B14,DARSO,2,FALSE) -> 45.7 | D14: =VLOOKUP(B14,DARSO,4,FALSE) -> 43.17 | E14: =VLOOKUP(B14,DARSO,5,FALSE) -> 0 | F14: =VLOOKUP(B14,DARSO,6,FALSE) -> 0 | G14: =SUM(D14:F14) -> 43.17 | H14: =VLOOKUP(B14,DARSO,3,FALSE) -> 101 | I14: =G14/C14 -> 0.94463895 | J14: =H14/C14 -> 2.2100656 | K14: =VLOOKUP(B14,year2022to23,311,FALSE) -> 797.25 | L14: =SUM(AD14:AO14) -> 1006.85 | M14: =K14/C14 -> 17.445295 | N14: =L14/C14 -> 22.031729 | AD14: =VLOOKUP(B14,ffbbudgettwofive,7,FALSE) -> 50.25 | AE14: =VLOOKUP(B14,ffbbudgettwofive,8,FALSE) -> 40.2 | AF14: =VLOOKUP(B14,ffbbudgettwofive,9,FALSE) -> 70.35 | AG14: =VLOOKUP(B14,ffbbudgettwofive,10,FALSE) -> 70.35 | AH14: =VLOOKUP(B14,ffbbudgettwofive,11,FALSE) -> 70.35 | AI14: =VLOOKUP(B14,ffbbudgettwofive,12,FALSE) -> 70.35 | AJ14: =VLOOKUP(B14,ffbbudgettwofive,13,FALSE) -> 80 | AK14: =VLOOKUP(B14,ffbbudgettwofive,14,FALSE) -> 101 | AL14: =VLOOKUP(B14,ffbbudgettwofive,15,FALSE) -> 101 | AM14: =VLOOKUP(B14,ffbbudgettwofive,16,FALSE) -> 141 | AN14: =VLOOKUP(B14,ffbbudgettwofive,17,FALSE) -> 111 | AO14: =VLOOKUP(B14,ffbbudgettwofive,18,FALSE) -> 101
B15: 19 | C15: =VLOOKUP(B15,DARSO,2,FALSE) -> 50.62 | D15: =VLOOKUP(B15,DARSO,4,FALSE) -> 56.22 | E15: =VLOOKUP(B15,DARSO,5,FALSE) -> 33.75 | F15: =VLOOKUP(B15,DARSO,6,FALSE) -> 0 | G15: =SUM(D15:F15) -> 89.97 | H15: =VLOOKUP(B15,DARSO,3,FALSE) -> 106 | I15: =G15/C15 -> 1.7773607 | J15: =H15/C15 -> 2.094034 | K15: =VLOOKUP(B15,year2022to23,311,FALSE) -> 866 | L15: =SUM(AD15:AO15) -> 1062.31 | M15: =K15/C15 -> 17.107863 | N15: =L15/C15 -> 20.985974 | AD15: =VLOOKUP(B15,ffbbudgettwofive,7,FALSE) -> 53.15 | AE15: =VLOOKUP(B15,ffbbudgettwofive,8,FALSE) -> 42.52 | AF15: =VLOOKUP(B15,ffbbudgettwofive,9,FALSE) -> 74.41 | AG15: =VLOOKUP(B15,ffbbudgettwofive,10,FALSE) -> 74.41 | AH15: =VLOOKUP(B15,ffbbudgettwofive,11,FALSE) -> 74.41 | AI15: =VLOOKUP(B15,ffbbudgettwofive,12,FALSE) -> 74.41 | AJ15: =VLOOKUP(B15,ffbbudgettwofive,13,FALSE) -> 85 | AK15: =VLOOKUP(B15,ffbbudgettwofive,14,FALSE) -> 106 | AL15: =VLOOKUP(B15,ffbbudgettwofive,15,FALSE) -> 106 | AM15: =VLOOKUP(B15,ffbbudgettwofive,16,FALSE) -> 149 | AN15: =VLOOKUP(B15,ffbbudgettwofive,17,FALSE) -> 117 | AO15: =VLOOKUP(B15,ffbbudgettwofive,18,FALSE) -> 106
B16: 20 | C16: =VLOOKUP(B16,DARSO,2,FALSE) -> 62.08 | D16: =VLOOKUP(B16,DARSO,4,FALSE) -> 84.19 | E16: =VLOOKUP(B16,DARSO,5,FALSE) -> 52.47 | F16: =VLOOKUP(B16,DARSO,6,FALSE) -> 0 | G16: =SUM(D16:F16) -> 136.66 | H16: =VLOOKUP(B16,DARSO,3,FALSE) -> 130 | I16: =G16/C16 -> 2.2013531 | J16: =H16/C16 -> 2.0940722 | K16: =VLOOKUP(B16,year2022to23,311,FALSE) -> 1028.6 | L16: =SUM(AD16:AO16) -> 1302.48 | M16: =K16/C16 -> 16.568943 | N16: =L16/C16 -> 20.98067 | AD16: =VLOOKUP(B16,ffbbudgettwofive,7,FALSE) -> 65.2 | AE16: =VLOOKUP(B16,ffbbudgettwofive,8,FALSE) -> 52.16 | AF16: =VLOOKUP(B16,ffbbudgettwofive,9,FALSE) -> 91.28 | AG16: =VLOOKUP(B16,ffbbudgettwofive,10,FALSE) -> 91.28 | AH16: =VLOOKUP(B16,ffbbudgettwofive,11,FALSE) -> 91.28 | AI16: =VLOOKUP(B16,ffbbudgettwofive,12,FALSE) -> 91.28 | AJ16: =VLOOKUP(B16,ffbbudgettwofive,13,FALSE) -> 104 | AK16: =VLOOKUP(B16,ffbbudgettwofive,14,FALSE) -> 130 | AL16: =VLOOKUP(B16,ffbbudgettwofive,15,FALSE) -> 130 | AM16: =VLOOKUP(B16,ffbbudgettwofive,16,FALSE) -> 183 | AN16: =VLOOKUP(B16,ffbbudgettwofive,17,FALSE) -> 143 | AO16: =VLOOKUP(B16,ffbbudgettwofive,18,FALSE) -> 130
B17: 21 | C17: =VLOOKUP(B17,DARSO,2,FALSE) -> 72.2 | D17: =VLOOKUP(B17,DARSO,4,FALSE) -> 101.3 | E17: =VLOOKUP(B17,DARSO,5,FALSE) -> 20.9 | F17: =VLOOKUP(B17,DARSO,6,FALSE) -> 0 | G17: =SUM(D17:F17) -> 122.2 | H17: =VLOOKUP(B17,DARSO,3,FALSE) -> 166 | I17: =G17/C17 -> 1.6925208 | J17: =H17/C17 -> 2.299169 | K17: =VLOOKUP(B17,year2022to23,311,FALSE) -> 1324.41 | L17: =SUM(AD17:AO17) -> 1660.57 | M17: =K17/C17 -> 18.343629 | N17: =L17/C17 -> 22.999584 | AD17: =VLOOKUP(B17,ffbbudgettwofive,7,FALSE) -> 83.05 | AE17: =VLOOKUP(B17,ffbbudgettwofive,8,FALSE) -> 66.44 | AF17: =VLOOKUP(B17,ffbbudgettwofive,9,FALSE) -> 116.27 | AG17: =VLOOKUP(B17,ffbbudgettwofive,10,FALSE) -> 116.27 | AH17: =VLOOKUP(B17,ffbbudgettwofive,11,FALSE) -> 116.27 | AI17: =VLOOKUP(B17,ffbbudgettwofive,12,FALSE) -> 116.27 | AJ17: =VLOOKUP(B17,ffbbudgettwofive,13,FALSE) -> 133 | AK17: =VLOOKUP(B17,ffbbudgettwofive,14,FALSE) -> 166 | AL17: =VLOOKUP(B17,ffbbudgettwofive,15,FALSE) -> 166 | AM17: =VLOOKUP(B17,ffbbudgettwofive,16,FALSE) -> 232 | AN17: =VLOOKUP(B17,ffbbudgettwofive,17,FALSE) -> 183 | AO17: =VLOOKUP(B17,ffbbudgettwofive,18,FALSE) -> 166
B18: 22 | C18: =VLOOKUP(B18,DARSO,2,FALSE) -> 52.3 | D18: =VLOOKUP(B18,DARSO,4,FALSE) -> 64.45 | E18: =VLOOKUP(B18,DARSO,5,FALSE) -> 0 | F18: =VLOOKUP(B18,DARSO,6,FALSE) -> 0 | G18: =SUM(D18:F18) -> 64.45 | H18: =VLOOKUP(B18,DARSO,3,FALSE) -> 110 | I18: =G18/C18 -> 1.2323136 | J18: =H18/C18 -> 2.1032505 | K18: =VLOOKUP(B18,year2022to23,311,FALSE) -> 845.84 | L18: =SUM(AD18:AO18) -> 1099.26 | M18: =K18/C18 -> 16.172849 | N18: =L18/C18 -> 21.018356 | AD18: =VLOOKUP(B18,ffbbudgettwofive,7,FALSE) -> 54.9 | AE18: =VLOOKUP(B18,ffbbudgettwofive,8,FALSE) -> 43.92 | AF18: =VLOOKUP(B18,ffbbudgettwofive,9,FALSE) -> 76.86 | AG18: =VLOOKUP(B18,ffbbudgettwofive,10,FALSE) -> 76.86 | AH18: =VLOOKUP(B18,ffbbudgettwofive,11,FALSE) -> 76.86 | AI18: =VLOOKUP(B18,ffbbudgettwofive,12,FALSE) -> 76.86 | AJ18: =VLOOKUP(B18,ffbbudgettwofive,13,FALSE) -> 88 | AK18: =VLOOKUP(B18,ffbbudgettwofive,14,FALSE) -> 110 | AL18: =VLOOKUP(B18,ffbbudgettwofive,15,FALSE) -> 110 | AM18: =VLOOKUP(B18,ffbbudgettwofive,16,FALSE) -> 154 | AN18: =VLOOKUP(B18,ffbbudgettwofive,17,FALSE) -> 121 | AO18: =VLOOKUP(B18,ffbbudgettwofive,18,FALSE) -> 110
A20: YUDI GANG -previously ERDI GANG | C20: ='YUDI GANG'!B10 -> 116.28 | D20: ='YUDI GANG'!D10 -> 94.47 | E20: ='YUDI GANG'!E10 -> 10.38 | F20: ='YUDI GANG'!F10 -> 0 | G20: =SUM(D20:F20) -> 104.85 | H20: ='YUDI GANG'!C10 -> 213 | I20: =G20/C20 -> 0.90170279 | J20: =H20/C20 -> 1.8317853 | K20: =SUM(K21:K23) -> 1517 | L20: =SUM(L21:L23) -> 2126.51 | M20: =K20/C20 -> 13.046096 | N20: =L20/C20 -> 18.28784 | AD20: Jan | AE20: Feb | AF20: Mar | AG20: Apr | AH20: May | AI20: Jun | AJ20: Jul | AK20: Aug | AL20: Sep | AM20: Oct | AN20: Nov | AO20: Dec
B21: 2 | C21: =VLOOKUP(B21,ERDI,2,FALSE) -> 60.4 | D21: =VLOOKUP(B21,ERDI,4,FALSE) -> 57.31 | E21: =VLOOKUP(B21,ERDI,5,FALSE) -> 0 | F21: =VLOOKUP(B21,ERDI,6,FALSE) -> 0 | G21: =SUM(D21:F21) -> 57.31 | H21: =VLOOKUP(B21,ERDI,3,FALSE) -> 121 | I21: =G21/C21 -> 0.94884106 | J21: =H21/C21 -> 2.0033113 | K21: =VLOOKUP(B21,year2022to23,311,FALSE) -> 889.57 | L21: =SUM(AD21:AO21) -> 1208.96 | M21: =K21/C21 -> 14.72798 | N21: =L21/C21 -> 20.015894 | AD21: =VLOOKUP(B21,ffbbudgettwofive,7,FALSE) -> 60.4 | AE21: =VLOOKUP(B21,ffbbudgettwofive,8,FALSE) -> 48.32 | AF21: =VLOOKUP(B21,ffbbudgettwofive,9,FALSE) -> 84.56 | AG21: =VLOOKUP(B21,ffbbudgettwofive,10,FALSE) -> 84.56 | AH21: =VLOOKUP(B21,ffbbudgettwofive,11,FALSE) -> 84.56 | AI21: =VLOOKUP(B21,ffbbudgettwofive,12,FALSE) -> 84.56 | AJ21: =VLOOKUP(B21,ffbbudgettwofive,13,FALSE) -> 97 | AK21: =VLOOKUP(B21,ffbbudgettwofive,14,FALSE) -> 121 | AL21: =VLOOKUP(B21,ffbbudgettwofive,15,FALSE) -> 121 | AM21: =VLOOKUP(B21,ffbbudgettwofive,16,FALSE) -> 169 | AN21: =VLOOKUP(B21,ffbbudgettwofive,17,FALSE) -> 133 | AO21: =VLOOKUP(B21,ffbbudgettwofive,18,FALSE) -> 121
B22: 11 | C22: =VLOOKUP(B22,ERDI,2,FALSE) -> 44.5 | D22: =VLOOKUP(B22,ERDI,4,FALSE) -> 32.42 | E22: =VLOOKUP(B22,ERDI,5,FALSE) -> 0 | F22: =VLOOKUP(B22,ERDI,6,FALSE) -> 0 | G22: =SUM(D22:F22) -> 32.42 | H22: =VLOOKUP(B22,ERDI,3,FALSE) -> 85 | I22: =G22/C22 -> 0.72853933 | J22: =H22/C22 -> 1.9101124 | K22: =VLOOKUP(B22,year2022to23,311,FALSE) -> 529.89 | L22: =SUM(AD22:AO22) -> 847.02 | M22: =K22/C22 -> 11.90764 | N22: =L22/C22 -> 19.034157 | AD22: =VLOOKUP(B22,ffbbudgettwofive,7,FALSE) -> 42.3 | AE22: =VLOOKUP(B22,ffbbudgettwofive,8,FALSE) -> 33.84 | AF22: =VLOOKUP(B22,ffbbudgettwofive,9,FALSE) -> 59.22 | AG22: =VLOOKUP(B22,ffbbudgettwofive,10,FALSE) -> 59.22 | AH22: =VLOOKUP(B22,ffbbudgettwofive,11,FALSE) -> 59.22 | AI22: =VLOOKUP(B22,ffbbudgettwofive,12,FALSE) -> 59.22 | AJ22: =VLOOKUP(B22,ffbbudgettwofive,13,FALSE) -> 68 | AK22: =VLOOKUP(B22,ffbbudgettwofive,14,FALSE) -> 85 | AL22: =VLOOKUP(B22,ffbbudgettwofive,15,FALSE) -> 85 | AM22: =VLOOKUP(B22,ffbbudgettwofive,16,FALSE) -> 118 | AN22: =VLOOKUP(B22,ffbbudgettwofive,17,FALSE) -> 93 | AO22: =VLOOKUP(B22,ffbbudgettwofive,18,FALSE) -> 85
B23: 29 | C23: =VLOOKUP(B23,ERDI,2,FALSE) -> 11.38 | D23: =VLOOKUP(B23,ERDI,4,FALSE) -> 4.74 | E23: =VLOOKUP(B23,ERDI,5,FALSE) -> 10.38 | F23: =VLOOKUP(B23,ERDI,6,FALSE) -> 0 | G23: =SUM(D23:F23) -> 15.12 | H23: =VLOOKUP(B23,ERDI,3,FALSE) -> 7 | I23: =G23/C23 -> 1.3286467 | J23: =H23/C23 -> 0.61511424 | K23: =VLOOKUP(B23,year2022to23,311,FALSE) -> 97.54 | L23: =SUM(AD23:AO23) -> 70.53 | M23: =K23/C23 -> 8.5711775 | N23: =L23/C23 -> 6.1977153 | AD23: =VLOOKUP(B23,ffbbudgettwofive,7,FALSE) -> 3.45 | AE23: =VLOOKUP(B23,ffbbudgettwofive,8,FALSE) -> 2.76 | AF23: =VLOOKUP(B23,ffbbudgettwofive,9,FALSE) -> 4.83 | AG23: =VLOOKUP(B23,ffbbudgettwofive,10,FALSE) -> 4.83 | AH23: =VLOOKUP(B23,ffbbudgettwofive,11,FALSE) -> 4.83 | AI23: =VLOOKUP(B23,ffbbudgettwofive,12,FALSE) -> 4.83 | AJ23: =VLOOKUP(B23,ffbbudgettwofive,13,FALSE) -> 6 | AK23: =VLOOKUP(B23,ffbbudgettwofive,14,FALSE) -> 7 | AL23: =VLOOKUP(B23,ffbbudgettwofive,15,FALSE) -> 7 | AM23: =VLOOKUP(B23,ffbbudgettwofive,16,FALSE) -> 10 | AN23: =VLOOKUP(B23,ffbbudgettwofive,17,FALSE) -> 8 | AO23: =VLOOKUP(B23,ffbbudgettwofive,18,FALSE) -> 7
A25: SOFIO MODENTUS MISSA GANG - previously SERAN | C25: ='SOFIO GANG'!B13 -> 262.5 | D25: ='SOFIO GANG'!D13 -> 267.13 | E25: ='SOFIO GANG'!E13 -> 97 | F25: ='SOFIO GANG'!F13 -> 0 | G25: =SUM(D25:F25) -> 364.13 | H25: ='SOFIO GANG'!C13 -> 511 | I25: =G25/C25 -> 1.3871619 | J25: =H25/C25 -> 1.9466667 | K25: =SUM(K26:K31) -> 4293.8 | L25: =ROUND(SUM(L26:L31),0) -> 5108 | M25: =K25/C25 -> 16.357333 | N25: =L25/C25 -> 19.459048 | AD25: Jan | AE25: Feb | AF25: Mar | AG25: Apr | AH25: May | AI25: Jun | AJ25: Jul | AK25: Aug | AL25: Sep | AM25: Oct | AN25: Nov | AO25: Dec
B26: 4 | C26: =VLOOKUP(B26,SERAN,2,FALSE) -> 70.6 | D26: =VLOOKUP(B26,SERAN,4,FALSE) -> 65.04 | E26: =VLOOKUP(B26,SERAN,5,FALSE) -> 0 | F26: =VLOOKUP(B26,SERAN,6,FALSE) -> 0 | G26: =SUM(D26:F26) -> 65.04 | H26: =VLOOKUP(B26,SERAN,3,FALSE) -> 141 | I26: =G26/C26 -> 0.92124646 | J26: =H26/C26 -> 1.9971671 | K26: =VLOOKUP(B26,year2022to23,311,FALSE) -> 1063.57 | L26: =SUM(AD26:AO26) -> 1411.44 | M26: =K26/C26 -> 15.064731 | N26: =L26/C26 -> 19.992068 | AD26: =VLOOKUP(B26,ffbbudgettwofive,7,FALSE) -> 70.6 | AE26: =VLOOKUP(B26,ffbbudgettwofive,8,FALSE) -> 56.48 | AF26: =VLOOKUP(B26,ffbbudgettwofive,9,FALSE) -> 98.84 | AG26: =VLOOKUP(B26,ffbbudgettwofive,10,FALSE) -> 98.84 | AH26: =VLOOKUP(B26,ffbbudgettwofive,11,FALSE) -> 98.84 | AI26: =VLOOKUP(B26,ffbbudgettwofive,12,FALSE) -> 98.84 | AJ26: =VLOOKUP(B26,ffbbudgettwofive,13,FALSE) -> 113 | AK26: =VLOOKUP(B26,ffbbudgettwofive,14,FALSE) -> 141 | AL26: =VLOOKUP(B26,ffbbudgettwofive,15,FALSE) -> 141 | AM26: =VLOOKUP(B26,ffbbudgettwofive,16,FALSE) -> 198 | AN26: =VLOOKUP(B26,ffbbudgettwofive,17,FALSE) -> 155 | AO26: =VLOOKUP(B26,ffbbudgettwofive,18,FALSE) -> 141
B27: 5 | C27: =VLOOKUP(B27,SERAN,2,FALSE) -> 50.4 | D27: =VLOOKUP(B27,SERAN,4,FALSE) -> 47.44 | E27: =VLOOKUP(B27,SERAN,5,FALSE) -> 32.09 | F27: =VLOOKUP(B27,SERAN,6,FALSE) -> 0 | G27: =SUM(D27:F27) -> 79.53 | H27: =VLOOKUP(B27,SERAN,3,FALSE) -> 101 | I27: =G27/C27 -> 1.5779762 | J27: =H27/C27 -> 2.0039683 | K27: =VLOOKUP(B27,year2022to23,311,FALSE) -> 835.29 | L27: =SUM(AD27:AO27) -> 1008.96 | M27: =K27/C27 -> 16.573214 | N27: =L27/C27 -> 20.019048 | AD27: =VLOOKUP(B27,ffbbudgettwofive,7,FALSE) -> 50.4 | AE27: =VLOOKUP(B27,ffbbudgettwofive,8,FALSE) -> 40.32 | AF27: =VLOOKUP(B27,ffbbudgettwofive,9,FALSE) -> 70.56 | AG27: =VLOOKUP(B27,ffbbudgettwofive,10,FALSE) -> 70.56 | AH27: =VLOOKUP(B27,ffbbudgettwofive,11,FALSE) -> 70.56 | AI27: =VLOOKUP(B27,ffbbudgettwofive,12,FALSE) -> 70.56 | AJ27: =VLOOKUP(B27,ffbbudgettwofive,13,FALSE) -> 81 | AK27: =VLOOKUP(B27,ffbbudgettwofive,14,FALSE) -> 101 | AL27: =VLOOKUP(B27,ffbbudgettwofive,15,FALSE) -> 101 | AM27: =VLOOKUP(B27,ffbbudgettwofive,16,FALSE) -> 141 | AN27: =VLOOKUP(B27,ffbbudgettwofive,17,FALSE) -> 111 | AO27: =VLOOKUP(B27,ffbbudgettwofive,18,FALSE) -> 101
B28: 6 | C28: =VLOOKUP(B28,SERAN,2,FALSE) -> 58.6 | D28: =VLOOKUP(B28,SERAN,4,FALSE) -> 60.33 | E28: =VLOOKUP(B28,SERAN,5,FALSE) -> 64.91 | F28: =VLOOKUP(B28,SERAN,6,FALSE) -> 0 | G28: =SUM(D28:F28) -> 125.24 | H28: =VLOOKUP(B28,SERAN,3,FALSE) -> 117 | I28: =G28/C28 -> 2.1372014 | J28: =H28/C28 -> 1.996587 | K28: =VLOOKUP(B28,year2022to23,311,FALSE) -> 961.24 | L28: =SUM(AD28:AO28) -> 1171.64 | M28: =K28/C28 -> 16.403413 | N28: =L28/C28 -> 19.993857 | AD28: =VLOOKUP(B28,ffbbudgettwofive,7,FALSE) -> 58.6 | AE28: =VLOOKUP(B28,ffbbudgettwofive,8,FALSE) -> 46.88 | AF28: =VLOOKUP(B28,ffbbudgettwofive,9,FALSE) -> 82.04 | AG28: =VLOOKUP(B28,ffbbudgettwofive,10,FALSE) -> 82.04 | AH28: =VLOOKUP(B28,ffbbudgettwofive,11,FALSE) -> 82.04 | AI28: =VLOOKUP(B28,ffbbudgettwofive,12,FALSE) -> 82.04 | AJ28: =VLOOKUP(B28,ffbbudgettwofive,13,FALSE) -> 94 | AK28: =VLOOKUP(B28,ffbbudgettwofive,14,FALSE) -> 117 | AL28: =VLOOKUP(B28,ffbbudgettwofive,15,FALSE) -> 117 | AM28: =VLOOKUP(B28,ffbbudgettwofive,16,FALSE) -> 164 | AN28: =VLOOKUP(B28,ffbbudgettwofive,17,FALSE) -> 129 | AO28: =VLOOKUP(B28,ffbbudgettwofive,18,FALSE) -> 117
B29: 7 | C29: =VLOOKUP(B29,SERAN,2,FALSE) -> 23.6 | D29: =VLOOKUP(B29,SERAN,4,FALSE) -> 19.15 | E29: =VLOOKUP(B29,SERAN,5,FALSE) -> 0 | F29: =VLOOKUP(B29,SERAN,6,FALSE) -> 0 | G29: =SUM(D29:F29) -> 19.15 | H29: =VLOOKUP(B29,SERAN,3,FALSE) -> 40 | I29: =G29/C29 -> 0.81144068 | J29: =H29/C29 -> 1.6949153 | K29: =VLOOKUP(B29,year2022to23,311,FALSE) -> 334.61 | L29: =SUM(AD29:AO29) -> 400.37 | M29: =K29/C29 -> 14.17839 | N29: =L29/C29 -> 16.964831 | AD29: =VLOOKUP(B29,ffbbudgettwofive,7,FALSE) -> 20.05 | AE29: =VLOOKUP(B29,ffbbudgettwofive,8,FALSE) -> 16.04 | AF29: =VLOOKUP(B29,ffbbudgettwofive,9,FALSE) -> 28.07 | AG29: =VLOOKUP(B29,ffbbudgettwofive,10,FALSE) -> 28.07 | AH29: =VLOOKUP(B29,ffbbudgettwofive,11,FALSE) -> 28.07 | AI29: =VLOOKUP(B29,ffbbudgettwofive,12,FALSE) -> 28.07 | AJ29: =VLOOKUP(B29,ffbbudgettwofive,13,FALSE) -> 32 | AK29: =VLOOKUP(B29,ffbbudgettwofive,14,FALSE) -> 40 | AL29: =VLOOKUP(B29,ffbbudgettwofive,15,FALSE) -> 40 | AM29: =VLOOKUP(B29,ffbbudgettwofive,16,FALSE) -> 56 | AN29: =VLOOKUP(B29,ffbbudgettwofive,17,FALSE) -> 44 | AO29: =VLOOKUP(B29,ffbbudgettwofive,18,FALSE) -> 40
B30: 23 | C30: =VLOOKUP(B30,SERAN,2,FALSE) -> 14.6 | D30: =VLOOKUP(B30,SERAN,4,FALSE) -> 25.26 | E30: =VLOOKUP(B30,SERAN,5,FALSE) -> 0 | F30: =VLOOKUP(B30,SERAN,6,FALSE) -> 0 | G30: =SUM(D30:F30) -> 25.26 | H30: =VLOOKUP(B30,SERAN,3,FALSE) -> 31 | I30: =G30/C30 -> 1.730137 | J30: =H30/C30 -> 2.1232877 | K30: =VLOOKUP(B30,year2022to23,311,FALSE) -> 291.61 | L30: =SUM(AD30:AO30) -> 308.59 | M30: =K30/C30 -> 19.973288 | N30: =L30/C30 -> 21.136301 | AD30: =VLOOKUP(B30,ffbbudgettwofive,7,FALSE) -> 15.35 | AE30: =VLOOKUP(B30,ffbbudgettwofive,8,FALSE) -> 12.28 | AF30: =VLOOKUP(B30,ffbbudgettwofive,9,FALSE) -> 21.49 | AG30: =VLOOKUP(B30,ffbbudgettwofive,10,FALSE) -> 21.49 | AH30: =VLOOKUP(B30,ffbbudgettwofive,11,FALSE) -> 21.49 | AI30: =VLOOKUP(B30,ffbbudgettwofive,12,FALSE) -> 21.49 | AJ30: =VLOOKUP(B30,ffbbudgettwofive,13,FALSE) -> 25 | AK30: =VLOOKUP(B30,ffbbudgettwofive,14,FALSE) -> 31 | AL30: =VLOOKUP(B30,ffbbudgettwofive,15,FALSE) -> 31 | AM30: =VLOOKUP(B30,ffbbudgettwofive,16,FALSE) -> 43 | AN30: =VLOOKUP(B30,ffbbudgettwofive,17,FALSE) -> 34 | AO30: =VLOOKUP(B30,ffbbudgettwofive,18,FALSE) -> 31
B31: 24 | C31: =VLOOKUP(B31,SERAN,2,FALSE) -> 44.7 | D31: =VLOOKUP(B31,SERAN,4,FALSE) -> 49.91 | E31: =VLOOKUP(B31,SERAN,5,FALSE) -> 0 | F31: =VLOOKUP(B31,SERAN,6,FALSE) -> 0 | G31: =SUM(D31:F31) -> 49.91 | H31: =VLOOKUP(B31,SERAN,3,FALSE) -> 81 | I31: =G31/C31 -> 1.1165548 | J31: =H31/C31 -> 1.8120805 | K31: =VLOOKUP(B31,year2022to23,311,FALSE) -> 807.48 | L31: =SUM(AD31:AO31) -> 806.85 | M31: =K31/C31 -> 18.06443 | N31: =L31/C31 -> 18.050336 | AD31: =VLOOKUP(B31,ffbbudgettwofive,7,FALSE) -> 40.25 | AE31: =VLOOKUP(B31,ffbbudgettwofive,8,FALSE) -> 32.2 | AF31: =VLOOKUP(B31,ffbbudgettwofive,9,FALSE) -> 56.35 | AG31: =VLOOKUP(B31,ffbbudgettwofive,10,FALSE) -> 56.35 | AH31: =VLOOKUP(B31,ffbbudgettwofive,11,FALSE) -> 56.35 | AI31: =VLOOKUP(B31,ffbbudgettwofive,12,FALSE) -> 56.35 | AJ31: =VLOOKUP(B31,ffbbudgettwofive,13,FALSE) -> 64 | AK31: =VLOOKUP(B31,ffbbudgettwofive,14,FALSE) -> 81 | AL31: =VLOOKUP(B31,ffbbudgettwofive,15,FALSE) -> 81 | AM31: =VLOOKUP(B31,ffbbudgettwofive,16,FALSE) -> 113 | AN31: =VLOOKUP(B31,ffbbudgettwofive,17,FALSE) -> 89 | AO31: =VLOOKUP(B31,ffbbudgettwofive,18,FALSE) -> 81
A33: NU AZANI GANG | C33: ='NU AZANI GANG'!B13 -> 291.6 | D33: ='NU AZANI GANG'!D13 -> 259.99 | E33: ='NU AZANI GANG'!E13 -> 145.63 | F33: ='NU AZANI GANG'!F13 -> 0 | G33: =SUM(D33:F33) -> 405.62 | H33: ='NU AZANI GANG'!C13 -> 594 | I33: =G33/C33 -> 1.3910151 | J33: =H33/C33 -> 2.037037 | K33: =SUM(K34:K39) -> 4491.63 | L33: =ROUND(SUM(L34:L39),0)-2 -> 5940 | M33: =K33/C33 -> 15.403395 | N33: =L33/C33 -> 20.37037 | AD33: Jan | AE33: Feb | AF33: Mar | AG33: Apr | AH33: May | AI33: Jun | AJ33: Jul | AK33: Aug | AL33: Sep | AM33: Oct | AN33: Nov | AO33: Dec
B34: 8 | C34: =VLOOKUP(B34,NURAZANI,2,FALSE) -> 61.6 | D34: =VLOOKUP(B34,NURAZANI,4,FALSE) -> 59.31 | E34: =VLOOKUP(B34,NURAZANI,5,FALSE) -> 7.63 | F34: =VLOOKUP(B34,NURAZANI,6,FALSE) -> 0 | G34: =SUM(D34:F34) -> 66.94 | H34: =VLOOKUP(B34,NURAZANI,3,FALSE) -> 123 | I34: =G34/C34 -> 1.0866883 | J34: =H34/C34 -> 1.9967532 | K34: =VLOOKUP(B34,year2022to23,311,FALSE) -> 906.12 | L34: =SUM(AD34:AO34) -> 1231.84 | M34: =K34/C34 -> 14.70974 | N34: =L34/C34 -> 19.997403 | AD34: =VLOOKUP(B34,ffbbudgettwofive,7,FALSE) -> 61.6 | AE34: =VLOOKUP(B34,ffbbudgettwofive,8,FALSE) -> 49.28 | AF34: =VLOOKUP(B34,ffbbudgettwofive,9,FALSE) -> 86.24 | AG34: =VLOOKUP(B34,ffbbudgettwofive,10,FALSE) -> 86.24 | AH34: =VLOOKUP(B34,ffbbudgettwofive,11,FALSE) -> 86.24 | AI34: =VLOOKUP(B34,ffbbudgettwofive,12,FALSE) -> 86.24 | AJ34: =VLOOKUP(B34,ffbbudgettwofive,13,FALSE) -> 99 | AK34: =VLOOKUP(B34,ffbbudgettwofive,14,FALSE) -> 123 | AL34: =VLOOKUP(B34,ffbbudgettwofive,15,FALSE) -> 123 | AM34: =VLOOKUP(B34,ffbbudgettwofive,16,FALSE) -> 172 | AN34: =VLOOKUP(B34,ffbbudgettwofive,17,FALSE) -> 136 | AO34: =VLOOKUP(B34,ffbbudgettwofive,18,FALSE) -> 123
B35: 9 | C35: =VLOOKUP(B35,NURAZANI,2,FALSE) -> 38.3 | D35: =VLOOKUP(B35,NURAZANI,4,FALSE) -> 33.01 | E35: =VLOOKUP(B35,NURAZANI,5,FALSE) -> 0 | F35: =VLOOKUP(B35,NURAZANI,6,FALSE) -> 0 | G35: =SUM(D35:F35) -> 33.01 | H35: =VLOOKUP(B35,NURAZANI,3,FALSE) -> 69 | I35: =G35/C35 -> 0.8618799 | J35: =H35/C35 -> 1.8015666 | K35: =VLOOKUP(B35,year2022to23,311,FALSE) -> 486.12 | L35: =SUM(AD35:AO35) -> 689.93 | M35: =K35/C35 -> 12.692428 | N35: =L35/C35 -> 18.013838 | AD35: =VLOOKUP(B35,ffbbudgettwofive,7,FALSE) -> 34.45 | AE35: =VLOOKUP(B35,ffbbudgettwofive,8,FALSE) -> 27.56 | AF35: =VLOOKUP(B35,ffbbudgettwofive,9,FALSE) -> 48.23 | AG35: =VLOOKUP(B35,ffbbudgettwofive,10,FALSE) -> 48.23 | AH35: =VLOOKUP(B35,ffbbudgettwofive,11,FALSE) -> 48.23 | AI35: =VLOOKUP(B35,ffbbudgettwofive,12,FALSE) -> 48.23 | AJ35: =VLOOKUP(B35,ffbbudgettwofive,13,FALSE) -> 55 | AK35: =VLOOKUP(B35,ffbbudgettwofive,14,FALSE) -> 69 | AL35: =VLOOKUP(B35,ffbbudgettwofive,15,FALSE) -> 69 | AM35: =VLOOKUP(B35,ffbbudgettwofive,16,FALSE) -> 97 | AN35: =VLOOKUP(B35,ffbbudgettwofive,17,FALSE) -> 76 | AO35: =VLOOKUP(B35,ffbbudgettwofive,18,FALSE) -> 69
B36: 12 | C36: =VLOOKUP(B36,NURAZANI,2,FALSE) -> 71 | D36: =VLOOKUP(B36,NURAZANI,4,FALSE) -> 49.47 | E36: =VLOOKUP(B36,NURAZANI,5,FALSE) -> 43.91 | F36: =VLOOKUP(B36,NURAZANI,6,FALSE) -> 0 | G36: =SUM(D36:F36) -> 93.38 | H36: =VLOOKUP(B36,NURAZANI,3,FALSE) -> 142 | I36: =G36/C36 -> 1.3152113 | J36: =H36/C36 -> 2 | K36: =VLOOKUP(B36,year2022to23,311,FALSE) -> 1000.74 | L36: =SUM(AD36:AO36) -> 1420.4 | M36: =K36/C36 -> 14.09493 | N36: =L36/C36 -> 20.005634 | AD36: =VLOOKUP(B36,ffbbudgettwofive,7,FALSE) -> 71 | AE36: =VLOOKUP(B36,ffbbudgettwofive,8,FALSE) -> 56.8 | AF36: =VLOOKUP(B36,ffbbudgettwofive,9,FALSE) -> 99.4 | AG36: =VLOOKUP(B36,ffbbudgettwofive,10,FALSE) -> 99.4 | AH36: =VLOOKUP(B36,ffbbudgettwofive,11,FALSE) -> 99.4 | AI36: =VLOOKUP(B36,ffbbudgettwofive,12,FALSE) -> 99.4 | AJ36: =VLOOKUP(B36,ffbbudgettwofive,13,FALSE) -> 114 | AK36: =VLOOKUP(B36,ffbbudgettwofive,14,FALSE) -> 142 | AL36: =VLOOKUP(B36,ffbbudgettwofive,15,FALSE) -> 142 | AM36: =VLOOKUP(B36,ffbbudgettwofive,16,FALSE) -> 199 | AN36: =VLOOKUP(B36,ffbbudgettwofive,17,FALSE) -> 156 | AO36: =VLOOKUP(B36,ffbbudgettwofive,18,FALSE) -> 142
B37: 10 | C37: =VLOOKUP(B37,NURAZANI,2,FALSE) -> 19.1 | D37: =VLOOKUP(B37,NURAZANI,4,FALSE) -> 13.41 | E37: =VLOOKUP(B37,NURAZANI,5,FALSE) -> 0 | F37: =VLOOKUP(B37,NURAZANI,6,FALSE) -> 0 | G37: =SUM(D37:F37) -> 13.41 | H37: =VLOOKUP(B37,NURAZANI,3,FALSE) -> 36 | I37: =G37/C37 -> 0.70209424 | J37: =H37/C37 -> 1.8848168 | K37: =VLOOKUP(B37,year2022to23,311,FALSE) -> 259.04 | L37: =SUM(AD37:AO37) -> 362.31 | M37: =K37/C37 -> 13.562304 | N37: =L37/C37 -> 18.96911 | AD37: =VLOOKUP(B37,ffbbudgettwofive,7,FALSE) -> 18.15 | AE37: =VLOOKUP(B37,ffbbudgettwofive,8,FALSE) -> 14.52 | AF37: =VLOOKUP(B37,ffbbudgettwofive,9,FALSE) -> 25.41 | AG37: =VLOOKUP(B37,ffbbudgettwofive,10,FALSE) -> 25.41 | AH37: =VLOOKUP(B37,ffbbudgettwofive,11,FALSE) -> 25.41 | AI37: =VLOOKUP(B37,ffbbudgettwofive,12,FALSE) -> 25.41 | AJ37: =VLOOKUP(B37,ffbbudgettwofive,13,FALSE) -> 29 | AK37: =VLOOKUP(B37,ffbbudgettwofive,14,FALSE) -> 36 | AL37: =VLOOKUP(B37,ffbbudgettwofive,15,FALSE) -> 36 | AM37: =VLOOKUP(B37,ffbbudgettwofive,16,FALSE) -> 51 | AN37: =VLOOKUP(B37,ffbbudgettwofive,17,FALSE) -> 40 | AO37: =VLOOKUP(B37,ffbbudgettwofive,18,FALSE) -> 36
B38: 13 | C38: =VLOOKUP(B38,NURAZANI,2,FALSE) -> 60.8 | D38: =VLOOKUP(B38,NURAZANI,4,FALSE) -> 59.58 | E38: =VLOOKUP(B38,NURAZANI,5,FALSE) -> 53.37 | F38: =VLOOKUP(B38,NURAZANI,6,FALSE) -> 0 | G38: =SUM(D38:F38) -> 112.95 | H38: =VLOOKUP(B38,NURAZANI,3,FALSE) -> 134 | I38: =G38/C38 -> 1.8577303 | J38: =H38/C38 -> 2.2039474 | K38: =VLOOKUP(B38,year2022to23,311,FALSE) -> 1038.9 | L38: =SUM(AD38:AO38) -> 1338.06 | M38: =K38/C38 -> 17.087171 | N38: =L38/C38 -> 22.007566 | AD38: =VLOOKUP(B38,ffbbudgettwofive,7,FALSE) -> 66.9 | AE38: =VLOOKUP(B38,ffbbudgettwofive,8,FALSE) -> 53.52 | AF38: =VLOOKUP(B38,ffbbudgettwofive,9,FALSE) -> 93.66 | AG38: =VLOOKUP(B38,ffbbudgettwofive,10,FALSE) -> 93.66 | AH38: =VLOOKUP(B38,ffbbudgettwofive,11,FALSE) -> 93.66 | AI38: =VLOOKUP(B38,ffbbudgettwofive,12,FALSE) -> 93.66 | AJ38: =VLOOKUP(B38,ffbbudgettwofive,13,FALSE) -> 107 | AK38: =VLOOKUP(B38,ffbbudgettwofive,14,FALSE) -> 134 | AL38: =VLOOKUP(B38,ffbbudgettwofive,15,FALSE) -> 134 | AM38: =VLOOKUP(B38,ffbbudgettwofive,16,FALSE) -> 187 | AN38: =VLOOKUP(B38,ffbbudgettwofive,17,FALSE) -> 147 | AO38: =VLOOKUP(B38,ffbbudgettwofive,18,FALSE) -> 134
B39: 18 | C39: =VLOOKUP(B39,NURAZANI,2,FALSE) -> 40.8 | D39: =VLOOKUP(B39,NURAZANI,4,FALSE) -> 45.21 | E39: =VLOOKUP(B39,NURAZANI,5,FALSE) -> 40.72 | F39: =VLOOKUP(B39,NURAZANI,6,FALSE) -> 0 | G39: =SUM(D39:F39) -> 85.93 | H39: =VLOOKUP(B39,NURAZANI,3,FALSE) -> 90 | I39: =G39/C39 -> 2.1061275 | J39: =H39/C39 -> 2.2058824 | K39: =VLOOKUP(B39,year2022to23,311,FALSE) -> 800.71 | L39: =SUM(AD39:AO39) -> 899.26 | M39: =K39/C39 -> 19.625245 | N39: =L39/C39 -> 22.040686 | AD39: =VLOOKUP(B39,ffbbudgettwofive,7,FALSE) -> 44.9 | AE39: =VLOOKUP(B39,ffbbudgettwofive,8,FALSE) -> 35.92 | AF39: =VLOOKUP(B39,ffbbudgettwofive,9,FALSE) -> 62.86 | AG39: =VLOOKUP(B39,ffbbudgettwofive,10,FALSE) -> 62.86 | AH39: =VLOOKUP(B39,ffbbudgettwofive,11,FALSE) -> 62.86 | AI39: =VLOOKUP(B39,ffbbudgettwofive,12,FALSE) -> 62.86 | AJ39: =VLOOKUP(B39,ffbbudgettwofive,13,FALSE) -> 72 | AK39: =VLOOKUP(B39,ffbbudgettwofive,14,FALSE) -> 90 | AL39: =VLOOKUP(B39,ffbbudgettwofive,15,FALSE) -> 90 | AM39: =VLOOKUP(B39,ffbbudgettwofive,16,FALSE) -> 126 | AN39: =VLOOKUP(B39,ffbbudgettwofive,17,FALSE) -> 99 | AO39: =VLOOKUP(B39,ffbbudgettwofive,18,FALSE) -> 90
A41: WENDERLINUS GANG | C41: ='WENDERLINUS GANG '!B15 -> 196.73 | D41: ='WENDERLINUS GANG '!D15 -> 109.34 | E41: ='WENDERLINUS GANG '!E15 -> 62.1 | F41: ='WENDERLINUS GANG '!F15 -> 0 | G41: =SUM(D41:F41) -> 171.44 | H41: ='WENDERLINUS GANG '!C15 -> 124 | I41: =G41/C41 -> 0.87144818 | J41: =H41/C41 -> 0.63030549 | K41: =SUM(K42:K49) -> 2108.47 | L41: =ROUND(SUM(L42:L49),0)-2 -> 1230 | M41: =K41/C41 -> 10.717582 | N41: =L41/C41 -> 6.2522239 | AD41: Jan | AE41: Feb | AF41: Mar | AG41: Apr | AH41: May | AI41: Jun | AJ41: Jul | AK41: Aug | AL41: Sep | AM41: Oct | AN41: Nov | AO41: Dec
B42: 25 | C42: =VLOOKUP(B42,WENDERLINUS,2,FALSE) -> 38.22 | D42: =VLOOKUP(B42,WENDERLINUS,4,FALSE) -> 12.27 | E42: =VLOOKUP(B42,WENDERLINUS,5,FALSE) -> 9.43 | F42: =VLOOKUP(B42,WENDERLINUS,6,FALSE) -> 0 | G42: =SUM(D42:F42) -> 21.7 | H42: =VLOOKUP(B42,WENDERLINUS,3,FALSE) -> 13 | I42: =G42/C42 -> 0.56776557 | J42: =H42/C42 -> 0.34013605 | K42: =VLOOKUP(B42,year2022to23,311,FALSE) -> 330.31 | L42: =SUM(AD42:AO42) -> 133.58 | M42: =K42/C42 -> 8.6423339 | N42: =L42/C42 -> 3.4950288 | AD42: =VLOOKUP(B42,ffbbudgettwofive,7,FALSE) -> 6.7 | AE42: =VLOOKUP(B42,ffbbudgettwofive,8,FALSE) -> 5.36 | AF42: =VLOOKUP(B42,ffbbudgettwofive,9,FALSE) -> 9.38 | AG42: =VLOOKUP(B42,ffbbudgettwofive,10,FALSE) -> 9.38 | AH42: =VLOOKUP(B42,ffbbudgettwofive,11,FALSE) -> 9.38 | AI42: =VLOOKUP(B42,ffbbudgettwofive,12,FALSE) -> 9.38 | AJ42: =VLOOKUP(B42,ffbbudgettwofive,13,FALSE) -> 11 | AK42: =VLOOKUP(B42,ffbbudgettwofive,14,FALSE) -> 13 | AL42: =VLOOKUP(B42,ffbbudgettwofive,15,FALSE) -> 13 | AM42: =VLOOKUP(B42,ffbbudgettwofive,16,FALSE) -> 19 | AN42: =VLOOKUP(B42,ffbbudgettwofive,17,FALSE) -> 15 | AO42: =VLOOKUP(B42,ffbbudgettwofive,18,FALSE) -> 13
B43: 26A | C43: =VLOOKUP(B43,WENDERLINUS,2,FALSE) -> 22.72 | D43: =VLOOKUP(B43,WENDERLINUS,4,FALSE) -> 10.02 | E43: =VLOOKUP(B43,WENDERLINUS,5,FALSE) -> 18.23 | F43: =VLOOKUP(B43,WENDERLINUS,6,FALSE) -> 0 | G43: =SUM(D43:F43) -> 28.25 | H43: =VLOOKUP(B43,WENDERLINUS,3,FALSE) -> 11 | I43: =G43/C43 -> 1.2433979 | J43: =H43/C43 -> 0.48415493 | K43: =VLOOKUP(B43,year2022to23,311,FALSE) -> 281.24 | L43: =SUM(AD43:AO43) -> 108.96 | M43: =K43/C43 -> 12.378521 | N43: =L43/C43 -> 4.7957746 | AD43: =VLOOKUP(B43,ffbbudgettwofive,7,FALSE) -> 5.4 | AE43: =VLOOKUP(B43,ffbbudgettwofive,8,FALSE) -> 4.32 | AF43: =VLOOKUP(B43,ffbbudgettwofive,9,FALSE) -> 7.56 | AG43: =VLOOKUP(B43,ffbbudgettwofive,10,FALSE) -> 7.56 | AH43: =VLOOKUP(B43,ffbbudgettwofive,11,FALSE) -> 7.56 | AI43: =VLOOKUP(B43,ffbbudgettwofive,12,FALSE) -> 7.56 | AJ43: =VLOOKUP(B43,ffbbudgettwofive,13,FALSE) -> 9 | AK43: =VLOOKUP(B43,ffbbudgettwofive,14,FALSE) -> 11 | AL43: =VLOOKUP(B43,ffbbudgettwofive,15,FALSE) -> 11 | AM43: =VLOOKUP(B43,ffbbudgettwofive,16,FALSE) -> 15 | AN43: =VLOOKUP(B43,ffbbudgettwofive,17,FALSE) -> 12 | AO43: =VLOOKUP(B43,ffbbudgettwofive,18,FALSE) -> 11
B44: 27 | C44: =VLOOKUP(B44,WENDERLINUS,2,FALSE) -> 18.64 | D44: =VLOOKUP(B44,WENDERLINUS,4,FALSE) -> 10 | E44: =VLOOKUP(B44,WENDERLINUS,5,FALSE) -> 9 | F44: =VLOOKUP(B44,WENDERLINUS,6,FALSE) -> 0 | G44: =SUM(D44:F44) -> 19 | H44: =VLOOKUP(B44,WENDERLINUS,3,FALSE) -> 9 | I44: =G44/C44 -> 1.0193133 | J44: =H44/C44 -> 0.48283262 | K44: =VLOOKUP(B44,year2022to23,311,FALSE) -> 191.64 | L44: =SUM(AD44:AO44) -> 86.82 | M44: =K44/C44 -> 10.281116 | N44: =L44/C44 -> 4.6577253 | AD44: =VLOOKUP(B44,ffbbudgettwofive,7,FALSE) -> 4.3 | AE44: =VLOOKUP(B44,ffbbudgettwofive,8,FALSE) -> 3.44 | AF44: =VLOOKUP(B44,ffbbudgettwofive,9,FALSE) -> 6.02 | AG44: =VLOOKUP(B44,ffbbudgettwofive,10,FALSE) -> 6.02 | AH44: =VLOOKUP(B44,ffbbudgettwofive,11,FALSE) -> 6.02 | AI44: =VLOOKUP(B44,ffbbudgettwofive,12,FALSE) -> 6.02 | AJ44: =VLOOKUP(B44,ffbbudgettwofive,13,FALSE) -> 7 | AK44: =VLOOKUP(B44,ffbbudgettwofive,14,FALSE) -> 9 | AL44: =VLOOKUP(B44,ffbbudgettwofive,15,FALSE) -> 9 | AM44: =VLOOKUP(B44,ffbbudgettwofive,16,FALSE) -> 12 | AN44: =VLOOKUP(B44,ffbbudgettwofive,17,FALSE) -> 9 | AO44: =VLOOKUP(B44,ffbbudgettwofive,18,FALSE) -> 9
B45: 28 | C45: =VLOOKUP(B45,WENDERLINUS,2,FALSE) -> 25.5 | D45: =VLOOKUP(B45,WENDERLINUS,4,FALSE) -> 23.75 | E45: =VLOOKUP(B45,WENDERLINUS,5,FALSE) -> 0 | F45: =VLOOKUP(B45,WENDERLINUS,6,FALSE) -> 0 | G45: =SUM(D45:F45) -> 23.75 | H45: =VLOOKUP(B45,WENDERLINUS,3,FALSE) -> 26 | I45: =G45/C45 -> 0.93137255 | J45: =H45/C45 -> 1.0196078 | K45: =VLOOKUP(B45,year2022to23,311,FALSE) -> 331.57 | L45: =SUM(AD45:AO45) -> 257.72 | M45: =K45/C45 -> 13.002745 | N45: =L45/C45 -> 10.106667 | AD45: =VLOOKUP(B45,ffbbudgettwofive,7,FALSE) -> 12.8 | AE45: =VLOOKUP(B45,ffbbudgettwofive,8,FALSE) -> 10.24 | AF45: =VLOOKUP(B45,ffbbudgettwofive,9,FALSE) -> 17.92 | AG45: =VLOOKUP(B45,ffbbudgettwofive,10,FALSE) -> 17.92 | AH45: =VLOOKUP(B45,ffbbudgettwofive,11,FALSE) -> 17.92 | AI45: =VLOOKUP(B45,ffbbudgettwofive,12,FALSE) -> 17.92 | AJ45: =VLOOKUP(B45,ffbbudgettwofive,13,FALSE) -> 21 | AK45: =VLOOKUP(B45,ffbbudgettwofive,14,FALSE) -> 26 | AL45: =VLOOKUP(B45,ffbbudgettwofive,15,FALSE) -> 26 | AM45: =VLOOKUP(B45,ffbbudgettwofive,16,FALSE) -> 36 | AN45: =VLOOKUP(B45,ffbbudgettwofive,17,FALSE) -> 28 | AO45: =VLOOKUP(B45,ffbbudgettwofive,18,FALSE) -> 26
...

Sheet OVERALL BY GANG COMPARISON YTD2
A1: YIELD TO DATE OF CURRENT YEAR VS. PAST YEAR
D4: Budget (MT) | E4: YTD (MT) | F4: Budget (MT) | G4: YTD (MT) | H4: Actual Variance (MT) | I4: YTD MT / HA
B5: O/P | C5: Total HA | D5: 2025 | F5: 2024 | H5: 2025 vs 2024 | I5: 2025 | J5: 2024 | Z5: 2025 FFB BUDGET
B6: =B7 -> 2010 | C6: =SUM(C7:C18) -> 616 | D6: =SUM(D7:D18) -> 12143 | E6: =SUM(E7:E18) -> 9294.3 | F6: =SUM(F7:F18) -> 12247 | G6: =SUM(G7:G18) -> 8876.255 | H6: =E6-G6 -> 418.045 | I6: =E6/C6 -> 15.088149 | J6: =G6/C6 -> 14.409505 | Z6: Jan | AA6: Feb | AB6: Mar | AC6: Apr | AD6: May | AE6: Jun | AF6: Jul | AG6: Aug | AH6: Sep | AI6: Oct | AJ6: Nov | AK6: Dec
A7: 1 | B7: =VLOOKUP(A7,coupe,3,FALSE) -> 2010 | C7: =VLOOKUP(A7,YUVENTUS,2,FALSE) -> 53.2 | D7: =VLOOKUP(A7,coupe,4,FALSE) -> 1064 | E7: =VLOOKUP(A7,year2022to23,311,FALSE) -> 909.79 | F7: =VLOOKUP(A7,budget2024,19,FALSE) -> 1064 | G7: =VLOOKUP(A7,year2022to23,249,FALSE) -> 707.14 | H7: =E7-G7 -> 202.65 | I7: =E7/C7 -> 17.101316 | J7: =G7/C7 -> 13.292105 | Z7: =VLOOKUP(A7,ffbbudgettwofive,7,FALSE) -> 53.2 | AA7: =VLOOKUP(A7,ffbbudgettwofive,8,FALSE) -> 42.56 | AB7: =VLOOKUP(A7,ffbbudgettwofive,9,FALSE) -> 74.48 | AC7: =VLOOKUP(A7,ffbbudgettwofive,10,FALSE) -> 74.48 | AD7: =VLOOKUP(A7,ffbbudgettwofive,11,FALSE) -> 74.48 | AE7: =VLOOKUP(A7,ffbbudgettwofive,12,FALSE) -> 74.48 | AF7: =VLOOKUP(A7,ffbbudgettwofive,13,FALSE) -> 85 | AG7: =VLOOKUP(A7,ffbbudgettwofive,14,FALSE) -> 106 | AH7: =VLOOKUP(A7,ffbbudgettwofive,15,FALSE) -> 106 | AI7: =VLOOKUP(A7,ffbbudgettwofive,16,FALSE) -> 149 | AJ7: =VLOOKUP(A7,ffbbudgettwofive,17,FALSE) -> 117 | AK7: =VLOOKUP(A7,ffbbudgettwofive,18,FALSE) -> 106
A8: 2 | B8: =VLOOKUP(A8,coupe,3,FALSE) -> 2010 | C8: =VLOOKUP(A8,ERDI,2,FALSE) -> 60.4 | D8: =VLOOKUP(A8,coupe,4,FALSE) -> 1208 | E8: =VLOOKUP(A8,year2022to23,311,FALSE) -> 889.57 | F8: =VLOOKUP(A8,budget2024,19,FALSE) -> 1208 | G8: =VLOOKUP(A8,year2022to23,249,FALSE) -> 828.714 | H8: =E8-G8 -> 60.856 | I8: =E8/C8 -> 14.72798 | J8: =G8/C8 -> 13.72043 | Z8: =VLOOKUP(A8,ffbbudgettwofive,7,FALSE) -> 60.4 | AA8: =VLOOKUP(A8,ffbbudgettwofive,8,FALSE) -> 48.32 | AB8: =VLOOKUP(A8,ffbbudgettwofive,9,FALSE) -> 84.56 | AC8: =VLOOKUP(A8,ffbbudgettwofive,10,FALSE) -> 84.56 | AD8: =VLOOKUP(A8,ffbbudgettwofive,11,FALSE) -> 84.56 | AE8: =VLOOKUP(A8,ffbbudgettwofive,12,FALSE) -> 84.56 | AF8: =VLOOKUP(A8,ffbbudgettwofive,13,FALSE) -> 97 | AG8: =VLOOKUP(A8,ffbbudgettwofive,14,FALSE) -> 121 | AH8: =VLOOKUP(A8,ffbbudgettwofive,15,FALSE) -> 121 | AI8: =VLOOKUP(A8,ffbbudgettwofive,16,FALSE) -> 169 | AJ8: =VLOOKUP(A8,ffbbudgettwofive,17,FALSE) -> 133 | AK8: =VLOOKUP(A8,ffbbudgettwofive,18,FALSE) -> 121
A9: 3 | B9: =VLOOKUP(A9,coupe,3,FALSE) -> 2010 | C9: =VLOOKUP(A9,YUVENTUS,2,FALSE) -> 69.2 | D9: =VLOOKUP(A9,coupe,4,FALSE) -> 1384 | E9: =VLOOKUP(A9,year2022to23,311,FALSE) -> 1085.75 | F9: =VLOOKUP(A9,budget2024,19,FALSE) -> 1384 | G9: =VLOOKUP(A9,year2022to23,249,FALSE) -> 927.07 | H9: =E9-G9 -> 158.68 | I9: =E9/C9 -> 15.690029 | J9: =G9/C9 -> 13.396965 | Z9: =VLOOKUP(A9,ffbbudgettwofive,7,FALSE) -> 69.2 | AA9: =VLOOKUP(A9,ffbbudgettwofive,8,FALSE) -> 55.36 | AB9: =VLOOKUP(A9,ffbbudgettwofive,9,FALSE) -> 96.88 | AC9: =VLOOKUP(A9,ffbbudgettwofive,10,FALSE) -> 96.88 | AD9: =VLOOKUP(A9,ffbbudgettwofive,11,FALSE) -> 96.88 | AE9: =VLOOKUP(A9,ffbbudgettwofive,12,FALSE) -> 96.88 | AF9: =VLOOKUP(A9,ffbbudgettwofive,13,FALSE) -> 111 | AG9: =VLOOKUP(A9,ffbbudgettwofive,14,FALSE) -> 138 | AH9: =VLOOKUP(A9,ffbbudgettwofive,15,FALSE) -> 138 | AI9: =VLOOKUP(A9,ffbbudgettwofive,16,FALSE) -> 194 | AJ9: =VLOOKUP(A9,ffbbudgettwofive,17,FALSE) -> 152 | AK9: =VLOOKUP(A9,ffbbudgettwofive,18,FALSE) -> 138
A10: 4 | B10: =VLOOKUP(A10,coupe,3,FALSE) -> 2010 | C10: =VLOOKUP(A10,SERAN,2,FALSE) -> 70.6 | D10: =VLOOKUP(A10,coupe,4,FALSE) -> 1412 | E10: =VLOOKUP(A10,year2022to23,311,FALSE) -> 1063.57 | F10: =VLOOKUP(A10,budget2024,19,FALSE) -> 1412 | G10: =VLOOKUP(A10,year2022to23,249,FALSE) -> 1027.433 | H10: =E10-G10 -> 36.137 | I10: =E10/C10 -> 15.064731 | J10: =G10/C10 -> 14.552875 | Z10: =VLOOKUP(A10,ffbbudgettwofive,7,FALSE) -> 70.6 | AA10: =VLOOKUP(A10,ffbbudgettwofive,8,FALSE) -> 56.48 | AB10: =VLOOKUP(A10,ffbbudgettwofive,9,FALSE) -> 98.84 | AC10: =VLOOKUP(A10,ffbbudgettwofive,10,FALSE) -> 98.84 | AD10: =VLOOKUP(A10,ffbbudgettwofive,11,FALSE) -> 98.84 | AE10: =VLOOKUP(A10,ffbbudgettwofive,12,FALSE) -> 98.84 | AF10: =VLOOKUP(A10,ffbbudgettwofive,13,FALSE) -> 113 | AG10: =VLOOKUP(A10,ffbbudgettwofive,14,FALSE) -> 141 | AH10: =VLOOKUP(A10,ffbbudgettwofive,15,FALSE) -> 141 | AI10: =VLOOKUP(A10,ffbbudgettwofive,16,FALSE) -> 198 | AJ10: =VLOOKUP(A10,ffbbudgettwofive,17,FALSE) -> 155 | AK10: =VLOOKUP(A10,ffbbudgettwofive,18,FALSE) -> 141
A11: 5 | B11: =VLOOKUP(A11,coupe,3,FALSE) -> 2010 | C11: =VLOOKUP(A11,SERAN,2,FALSE) -> 50.4 | D11: =VLOOKUP(A11,coupe,4,FALSE) -> 1008 | E11: =VLOOKUP(A11,year2022to23,311,FALSE) -> 835.29 | F11: =VLOOKUP(A11,budget2024,19,FALSE) -> 1008 | G11: =VLOOKUP(A11,year2022to23,249,FALSE) -> 781.76 | H11: =E11-G11 -> 53.53 | I11: =E11/C11 -> 16.573214 | J11: =G11/C11 -> 15.511111 | Z11: =VLOOKUP(A11,ffbbudgettwofive,7,FALSE) -> 50.4 | AA11: =VLOOKUP(A11,ffbbudgettwofive,8,FALSE) -> 40.32 | AB11: =VLOOKUP(A11,ffbbudgettwofive,9,FALSE) -> 70.56 | AC11: =VLOOKUP(A11,ffbbudgettwofive,10,FALSE) -> 70.56 | AD11: =VLOOKUP(A11,ffbbudgettwofive,11,FALSE) -> 70.56 | AE11: =VLOOKUP(A11,ffbbudgettwofive,12,FALSE) -> 70.56 | AF11: =VLOOKUP(A11,ffbbudgettwofive,13,FALSE) -> 81 | AG11: =VLOOKUP(A11,ffbbudgettwofive,14,FALSE) -> 101 | AH11: =VLOOKUP(A11,ffbbudgettwofive,15,FALSE) -> 101 | AI11: =VLOOKUP(A11,ffbbudgettwofive,16,FALSE) -> 141 | AJ11: =VLOOKUP(A11,ffbbudgettwofive,17,FALSE) -> 111 | AK11: =VLOOKUP(A11,ffbbudgettwofive,18,FALSE) -> 101
A12: 6 | B12: =VLOOKUP(A12,coupe,3,FALSE) -> 2010 | C12: =VLOOKUP(A12,SERAN,2,FALSE) -> 58.6 | D12: =VLOOKUP(A12,coupe,4,FALSE) -> 1172 | E12: =VLOOKUP(A12,year2022to23,311,FALSE) -> 961.24 | F12: =VLOOKUP(A12,budget2024,19,FALSE) -> 1172 | G12: =VLOOKUP(A12,year2022to23,249,FALSE) -> 1014.32 | H12: =E12-G12 -> -53.08 | I12: =E12/C12 -> 16.403413 | J12: =G12/C12 -> 17.309215 | Z12: =VLOOKUP(A12,ffbbudgettwofive,7,FALSE) -> 58.6 | AA12: =VLOOKUP(A12,ffbbudgettwofive,8,FALSE) -> 46.88 | AB12: =VLOOKUP(A12,ffbbudgettwofive,9,FALSE) -> 82.04 | AC12: =VLOOKUP(A12,ffbbudgettwofive,10,FALSE) -> 82.04 | AD12: =VLOOKUP(A12,ffbbudgettwofive,11,FALSE) -> 82.04 | AE12: =VLOOKUP(A12,ffbbudgettwofive,12,FALSE) -> 82.04 | AF12: =VLOOKUP(A12,ffbbudgettwofive,13,FALSE) -> 94 | AG12: =VLOOKUP(A12,ffbbudgettwofive,14,FALSE) -> 117 | AH12: =VLOOKUP(A12,ffbbudgettwofive,15,FALSE) -> 117 | AI12: =VLOOKUP(A12,ffbbudgettwofive,16,FALSE) -> 164 | AJ12: =VLOOKUP(A12,ffbbudgettwofive,17,FALSE) -> 129 | AK12: =VLOOKUP(A12,ffbbudgettwofive,18,FALSE) -> 117
A13: 7 | B13: =VLOOKUP(A13,coupe,3,FALSE) -> 2010 | C13: =VLOOKUP(A13,SERAN,2,FALSE) -> 23.6 | D13: =VLOOKUP(A13,coupe,4,FALSE) -> 401 | E13: =VLOOKUP(A13,year2022to23,311,FALSE) -> 334.61 | F13: =VLOOKUP(A13,budget2024,19,FALSE) -> 401 | G13: =VLOOKUP(A13,year2022to23,249,FALSE) -> 351.984 | H13: =E13-G13 -> -17.374 | I13: =E13/C13 -> 14.17839 | J13: =G13/C13 -> 14.914576 | Z13: =VLOOKUP(A13,ffbbudgettwofive,7,FALSE) -> 20.05 | AA13: =VLOOKUP(A13,ffbbudgettwofive,8,FALSE) -> 16.04 | AB13: =VLOOKUP(A13,ffbbudgettwofive,9,FALSE) -> 28.07 | AC13: =VLOOKUP(A13,ffbbudgettwofive,10,FALSE) -> 28.07 | AD13: =VLOOKUP(A13,ffbbudgettwofive,11,FALSE) -> 28.07 | AE13: =VLOOKUP(A13,ffbbudgettwofive,12,FALSE) -> 28.07 | AF13: =VLOOKUP(A13,ffbbudgettwofive,13,FALSE) -> 32 | AG13: =VLOOKUP(A13,ffbbudgettwofive,14,FALSE) -> 40 | AH13: =VLOOKUP(A13,ffbbudgettwofive,15,FALSE) -> 40 | AI13: =VLOOKUP(A13,ffbbudgettwofive,16,FALSE) -> 56 | AJ13: =VLOOKUP(A13,ffbbudgettwofive,17,FALSE) -> 44 | AK13: =VLOOKUP(A13,ffbbudgettwofive,18,FALSE) -> 40
A14: 8 | B14: =VLOOKUP(A14,coupe,3,FALSE) -> 2010 | C14: =VLOOKUP(A14,NURAZANI,2,FALSE) -> 61.6 | D14: =VLOOKUP(A14,coupe,4,FALSE) -> 1232 | E14: =VLOOKUP(A14,year2022to23,311,FALSE) -> 906.12 | F14: =VLOOKUP(A14,budget2024,19,FALSE) -> 1232 | G14: =VLOOKUP(A14,year2022to23,249,FALSE) -> 924.42 | H14: =E14-G14 -> -18.3 | I14: =E14/C14 -> 14.70974 | J14: =G14/C14 -> 15.006818 | Z14: =VLOOKUP(A14,ffbbudgettwofive,7,FALSE) -> 61.6 | AA14: =VLOOKUP(A14,ffbbudgettwofive,8,FALSE) -> 49.28 | AB14: =VLOOKUP(A14,ffbbudgettwofive,9,FALSE) -> 86.24 | AC14: =VLOOKUP(A14,ffbbudgettwofive,10,FALSE) -> 86.24 | AD14: =VLOOKUP(A14,ffbbudgettwofive,11,FALSE) -> 86.24 | AE14: =VLOOKUP(A14,ffbbudgettwofive,12,FALSE) -> 86.24 | AF14: =VLOOKUP(A14,ffbbudgettwofive,13,FALSE) -> 99 | AG14: =VLOOKUP(A14,ffbbudgettwofive,14,FALSE) -> 123 | AH14: =VLOOKUP(A14,ffbbudgettwofive,15,FALSE) -> 123 | AI14: =VLOOKUP(A14,ffbbudgettwofive,16,FALSE) -> 172 | AJ14: =VLOOKUP(A14,ffbbudgettwofive,17,FALSE) -> 136 | AK14: =VLOOKUP(A14,ffbbudgettwofive,18,FALSE) -> 123
A15: 9 | B15: =VLOOKUP(A15,coupe,3,FALSE) -> 2010 | C15: =VLOOKUP(A15,NURAZANI,2,FALSE) -> 38.3 | D15: =VLOOKUP(A15,coupe,4,FALSE) -> 689 | E15: =VLOOKUP(A15,year2022to23,311,FALSE) -> 486.12 | F15: =VLOOKUP(A15,budget2024,19,FALSE) -> 689 | G15: =VLOOKUP(A15,year2022to23,249,FALSE) -> 489.69 | H15: =E15-G15 -> -3.57 | I15: =E15/C15 -> 12.692428 | J15: =G15/C15 -> 12.78564 | Z15: =VLOOKUP(A15,ffbbudgettwofive,7,FALSE) -> 34.45 | AA15: =VLOOKUP(A15,ffbbudgettwofive,8,FALSE) -> 27.56 | AB15: =VLOOKUP(A15,ffbbudgettwofive,9,FALSE) -> 48.23 | AC15: =VLOOKUP(A15,ffbbudgettwofive,10,FALSE) -> 48.23 | AD15: =VLOOKUP(A15,ffbbudgettwofive,11,FALSE) -> 48.23 | AE15: =VLOOKUP(A15,ffbbudgettwofive,12,FALSE) -> 48.23 | AF15: =VLOOKUP(A15,ffbbudgettwofive,13,FALSE) -> 55 | AG15: =VLOOKUP(A15,ffbbudgettwofive,14,FALSE) -> 69 | AH15: =VLOOKUP(A15,ffbbudgettwofive,15,FALSE) -> 69 | AI15: =VLOOKUP(A15,ffbbudgettwofive,16,FALSE) -> 97 | AJ15: =VLOOKUP(A15,ffbbudgettwofive,17,FALSE) -> 76 | AK15: =VLOOKUP(A15,ffbbudgettwofive,18,FALSE) -> 69
A16: 11 | B16: =VLOOKUP(A16,coupe,3,FALSE) -> 2010 | C16: =VLOOKUP(A16,ERDI,2,FALSE) -> 44.5 | D16: =VLOOKUP(A16,coupe,4,FALSE) -> 846 | E16: =VLOOKUP(A16,year2022to23,311,FALSE) -> 529.89 | F16: =VLOOKUP(A16,budget2024,19,FALSE) -> 846 | G16: =VLOOKUP(A16,year2022to23,249,FALSE) -> 539.214 | H16: =E16-G16 -> -9.324 | I16: =E16/C16 -> 11.90764 | J16: =G16/C16 -> 12.117169 | Z16: =VLOOKUP(A16,ffbbudgettwofive,7,FALSE) -> 42.3 | AA16: =VLOOKUP(A16,ffbbudgettwofive,8,FALSE) -> 33.84 | AB16: =VLOOKUP(A16,ffbbudgettwofive,9,FALSE) -> 59.22 | AC16: =VLOOKUP(A16,ffbbudgettwofive,10,FALSE) -> 59.22 | AD16: =VLOOKUP(A16,ffbbudgettwofive,11,FALSE) -> 59.22 | AE16: =VLOOKUP(A16,ffbbudgettwofive,12,FALSE) -> 59.22 | AF16: =VLOOKUP(A16,ffbbudgettwofive,13,FALSE) -> 68 | AG16: =VLOOKUP(A16,ffbbudgettwofive,14,FALSE) -> 85 | AH16: =VLOOKUP(A16,ffbbudgettwofive,15,FALSE) -> 85 | AI16: =VLOOKUP(A16,ffbbudgettwofive,16,FALSE) -> 118 | AJ16: =VLOOKUP(A16,ffbbudgettwofive,17,FALSE) -> 93 | AK16: =VLOOKUP(A16,ffbbudgettwofive,18,FALSE) -> 85
A17: 12 | B17: =VLOOKUP(A17,coupe,3,FALSE) -> 2010 | C17: =VLOOKUP(A17,NURAZANI,2,FALSE) -> 71 | D17: =VLOOKUP(A17,coupe,4,FALSE) -> 1420 | E17: =VLOOKUP(A17,year2022to23,311,FALSE) -> 1000.74 | F17: =VLOOKUP(A17,budget2024,19,FALSE) -> 1524 | G17: =VLOOKUP(A17,year2022to23,249,FALSE) -> 996.92 | H17: =E17-G17 -> 3.82 | I17: =E17/C17 -> 14.09493 | J17: =G17/C17 -> 14.041127 | Z17: =VLOOKUP(A17,ffbbudgettwofive,7,FALSE) -> 71 | AA17: =VLOOKUP(A17,ffbbudgettwofive,8,FALSE) -> 56.8 | AB17: =VLOOKUP(A17,ffbbudgettwofive,9,FALSE) -> 99.4 | AC17: =VLOOKUP(A17,ffbbudgettwofive,10,FALSE) -> 99.4 | AD17: =VLOOKUP(A17,ffbbudgettwofive,11,FALSE) -> 99.4 | AE17: =VLOOKUP(A17,ffbbudgettwofive,12,FALSE) -> 99.4 | AF17: =VLOOKUP(A17,ffbbudgettwofive,13,FALSE) -> 114 | AG17: =VLOOKUP(A17,ffbbudgettwofive,14,FALSE) -> 142 | AH17: =VLOOKUP(A17,ffbbudgettwofive,15,FALSE) -> 142 | AI17: =VLOOKUP(A17,ffbbudgettwofive,16,FALSE) -> 199 | AJ17: =VLOOKUP(A17,ffbbudgettwofive,17,FALSE) -> 156 | AK17: =VLOOKUP(A17,ffbbudgettwofive,18,FALSE) -> 142
A18: 23 | B18: =VLOOKUP(A18,coupe,3,FALSE) -> 2010 | C18: =VLOOKUP(A18,SERAN,2,FALSE) -> 14.6 | D18: =VLOOKUP(A18,coupe,4,FALSE) -> 307 | E18: =VLOOKUP(A18,year2022to23,311,FALSE) -> 291.61 | F18: =VLOOKUP(A18,budget2024,19,FALSE) -> 307 | G18: =VLOOKUP(A18,year2022to23,249,FALSE) -> 287.59 | H18: =E18-G18 -> 4.02 | I18: =E18/C18 -> 19.973288 | J18: =G18/C18 -> 19.697945 | Z18: =VLOOKUP(A18,ffbbudgettwofive,7,FALSE) -> 15.35 | AA18: =VLOOKUP(A18,ffbbudgettwofive,8,FALSE) -> 12.28 | AB18: =VLOOKUP(A18,ffbbudgettwofive,9,FALSE) -> 21.49 | AC18: =VLOOKUP(A18,ffbbudgettwofive,10,FALSE) -> 21.49 | AD18: =VLOOKUP(A18,ffbbudgettwofive,11,FALSE) -> 21.49 | AE18: =VLOOKUP(A18,ffbbudgettwofive,12,FALSE) -> 21.49 | AF18: =VLOOKUP(A18,ffbbudgettwofive,13,FALSE) -> 25 | AG18: =VLOOKUP(A18,ffbbudgettwofive,14,FALSE) -> 31 | AH18: =VLOOKUP(A18,ffbbudgettwofive,15,FALSE) -> 31 | AI18: =VLOOKUP(A18,ffbbudgettwofive,16,FALSE) -> 43 | AJ18: =VLOOKUP(A18,ffbbudgettwofive,17,FALSE) -> 34 | AK18: =VLOOKUP(A18,ffbbudgettwofive,18,FALSE) -> 31
B20: =B21 -> 2011 | C20: =SUM(C21:C27) -> 310.5 | D20: =SUM(D21:D27) -> 6528 | E20: =SUM(E21:E27) -> 5287.5 | F20: =SUM(F21:F27) -> 6528 | G20: =SUM(G21:G27) -> 5030.965 | H20: =E20-G20 -> 256.535 | I20: =E20/C20 -> 17.028986 | J20: =G20/C20 -> 16.202786 | Z20: Jan | AA20: Feb | AB20: Mar | AC20: Apr | AD20: May | AE20: Jun | AF20: Jul | AG20: Aug | AH20: Sep | AI20: Oct | AJ20: Nov | AK20: Dec
A21: 10 | B21: =VLOOKUP(A21,coupe,3,FALSE) -> 2011 | C21: =VLOOKUP(A21,NURAZANI,2,FALSE) -> 19.1 | D21: =VLOOKUP(A21,coupe,4,FALSE) -> 363 | E21: =VLOOKUP(A21,year2022to23,311,FALSE) -> 259.04 | F21: =VLOOKUP(A21,budget2024,19,FALSE) -> 363 | G21: =VLOOKUP(A21,year2022to23,249,FALSE) -> 260.8 | H21: =E21-G21 -> -1.76 | I21: =E21/C21 -> 13.562304 | J21: =G21/C21 -> 13.65445 | Z21: =VLOOKUP(A21,ffbbudgettwofive,7,FALSE) -> 18.15 | AA21: =VLOOKUP(A21,ffbbudgettwofive,8,FALSE) -> 14.52 | AB21: =VLOOKUP(A21,ffbbudgettwofive,9,FALSE) -> 25.41 | AC21: =VLOOKUP(A21,ffbbudgettwofive,10,FALSE) -> 25.41 | AD21: =VLOOKUP(A21,ffbbudgettwofive,11,FALSE) -> 25.41 | AE21: =VLOOKUP(A21,ffbbudgettwofive,12,FALSE) -> 25.41 | AF21: =VLOOKUP(A21,ffbbudgettwofive,13,FALSE) -> 29 | AG21: =VLOOKUP(A21,ffbbudgettwofive,14,FALSE) -> 36 | AH21: =VLOOKUP(A21,ffbbudgettwofive,15,FALSE) -> 36 | AI21: =VLOOKUP(A21,ffbbudgettwofive,16,FALSE) -> 51 | AJ21: =VLOOKUP(A21,ffbbudgettwofive,17,FALSE) -> 40 | AK21: =VLOOKUP(A21,ffbbudgettwofive,18,FALSE) -> 36
A22: 13 | B22: =VLOOKUP(A22,coupe,3,FALSE) -> 2011 | C22: =VLOOKUP(A22,NURAZANI,2,FALSE) -> 60.8 | D22: =VLOOKUP(A22,coupe,4,FALSE) -> 1338 | E22: =VLOOKUP(A22,year2022to23,311,FALSE) -> 1038.9 | F22: =VLOOKUP(A22,budget2024,19,FALSE) -> 1338 | G22: =VLOOKUP(A22,year2022to23,249,FALSE) -> 998.859 | H22: =E22-G22 -> 40.041 | I22: =E22/C22 -> 17.087171 | J22: =G22/C22 -> 16.428602 | Z22: =VLOOKUP(A22,ffbbudgettwofive,7,FALSE) -> 66.9 | AA22: =VLOOKUP(A22,ffbbudgettwofive,8,FALSE) -> 53.52 | AB22: =VLOOKUP(A22,ffbbudgettwofive,9,FALSE) -> 93.66 | AC22: =VLOOKUP(A22,ffbbudgettwofive,10,FALSE) -> 93.66 | AD22: =VLOOKUP(A22,ffbbudgettwofive,11,FALSE) -> 93.66 | AE22: =VLOOKUP(A22,ffbbudgettwofive,12,FALSE) -> 93.66 | AF22: =VLOOKUP(A22,ffbbudgettwofive,13,FALSE) -> 107 | AG22: =VLOOKUP(A22,ffbbudgettwofive,14,FALSE) -> 134 | AH22: =VLOOKUP(A22,ffbbudgettwofive,15,FALSE) -> 134 | AI22: =VLOOKUP(A22,ffbbudgettwofive,16,FALSE) -> 187 | AJ22: =VLOOKUP(A22,ffbbudgettwofive,17,FALSE) -> 147 | AK22: =VLOOKUP(A22,ffbbudgettwofive,18,FALSE) -> 134
A23: 14 | B23: =VLOOKUP(A23,coupe,3,FALSE) -> 2011 | C23: =VLOOKUP(A23,YUVENTUS,2,FALSE) -> 41.6 | D23: =VLOOKUP(A23,coupe,4,FALSE) -> 874 | E23: =VLOOKUP(A23,year2022to23,311,FALSE) -> 714.03 | F23: =VLOOKUP(A23,budget2024,19,FALSE) -> 874 | G23: =VLOOKUP(A23,year2022to23,249,FALSE) -> 762.686 | H23: =E23-G23 -> -48.656 | I23: =E23/C23 -> 17.164183 | J23: =G23/C23 -> 18.333798 | Z23: =VLOOKUP(A23,ffbbudgettwofive,7,FALSE) -> 43.7 | AA23: =VLOOKUP(A23,ffbbudgettwofive,8,FALSE) -> 34.96 | AB23: =VLOOKUP(A23,ffbbudgettwofive,9,FALSE) -> 61.18 | AC23: =VLOOKUP(A23,ffbbudgettwofive,10,FALSE) -> 61.18 | AD23: =VLOOKUP(A23,ffbbudgettwofive,11,FALSE) -> 61.18 | AE23: =VLOOKUP(A23,ffbbudgettwofive,12,FALSE) -> 61.18 | AF23: =VLOOKUP(A23,ffbbudgettwofive,13,FALSE) -> 70 | AG23: =VLOOKUP(A23,ffbbudgettwofive,14,FALSE) -> 87 | AH23: =VLOOKUP(A23,ffbbudgettwofive,15,FALSE) -> 87 | AI23: =VLOOKUP(A23,ffbbudgettwofive,16,FALSE) -> 122 | AJ23: =VLOOKUP(A23,ffbbudgettwofive,17,FALSE) -> 96 | AK23: =VLOOKUP(A23,ffbbudgettwofive,18,FALSE) -> 87
A24: 15 | B24: =VLOOKUP(A24,coupe,3,FALSE) -> 2011 | C24: =VLOOKUP(A24,DARSO,2,FALSE) -> 49.3 | D24: =VLOOKUP(A24,coupe,4,FALSE) -> 986 | E24: =VLOOKUP(A24,year2022to23,311,FALSE) -> 776.89 | F24: =VLOOKUP(A24,budget2024,19,FALSE) -> 986 | G24: =VLOOKUP(A24,year2022to23,249,FALSE) -> 619.76 | H24: =E24-G24 -> 157.13 | I24: =E24/C24 -> 15.758418 | J24: =G24/C24 -> 12.571197 | Z24: =VLOOKUP(A24,ffbbudgettwofive,7,FALSE) -> 49.3 | AA24: =VLOOKUP(A24,ffbbudgettwofive,8,FALSE) -> 39.44 | AB24: =VLOOKUP(A24,ffbbudgettwofive,9,FALSE) -> 69.02 | AC24: =VLOOKUP(A24,ffbbudgettwofive,10,FALSE) -> 69.02 | AD24: =VLOOKUP(A24,ffbbudgettwofive,11,FALSE) -> 69.02 | AE24: =VLOOKUP(A24,ffbbudgettwofive,12,FALSE) -> 69.02 | AF24: =VLOOKUP(A24,ffbbudgettwofive,13,FALSE) -> 79 | AG24: =VLOOKUP(A24,ffbbudgettwofive,14,FALSE) -> 99 | AH24: =VLOOKUP(A24,ffbbudgettwofive,15,FALSE) -> 99 | AI24: =VLOOKUP(A24,ffbbudgettwofive,16,FALSE) -> 138 | AJ24: =VLOOKUP(A24,ffbbudgettwofive,17,FALSE) -> 108 | AK24: =VLOOKUP(A24,ffbbudgettwofive,18,FALSE) -> 99
A25: 16 | B25: =VLOOKUP(A25,coupe,3,FALSE) -> 2011 | C25: =VLOOKUP(A25,DARSO,2,FALSE) -> 53.2 | D25: =VLOOKUP(A25,coupe,4,FALSE) -> 1064 | E25: =VLOOKUP(A25,year2022to23,311,FALSE) -> 900.68 | F25: =VLOOKUP(A25,budget2024,19,FALSE) -> 1064 | G25: =VLOOKUP(A25,year2022to23,249,FALSE) -> 837.23 | H25: =E25-G25 -> 63.45 | I25: =E25/C25 -> 16.930075 | J25: =G25/C25 -> 15.737406 | Z25: =VLOOKUP(A25,ffbbudgettwofive,7,FALSE) -> 53.2 | AA25: =VLOOKUP(A25,ffbbudgettwofive,8,FALSE) -> 42.56 | AB25: =VLOOKUP(A25,ffbbudgettwofive,9,FALSE) -> 74.48 | AC25: =VLOOKUP(A25,ffbbudgettwofive,10,FALSE) -> 74.48 | AD25: =VLOOKUP(A25,ffbbudgettwofive,11,FALSE) -> 74.48 | AE25: =VLOOKUP(A25,ffbbudgettwofive,12,FALSE) -> 74.48 | AF25: =VLOOKUP(A25,ffbbudgettwofive,13,FALSE) -> 85 | AG25: =VLOOKUP(A25,ffbbudgettwofive,14,FALSE) -> 106 | AH25: =VLOOKUP(A25,ffbbudgettwofive,15,FALSE) -> 106 | AI25: =VLOOKUP(A25,ffbbudgettwofive,16,FALSE) -> 149 | AJ25: =VLOOKUP(A25,ffbbudgettwofive,17,FALSE) -> 117 | AK25: =VLOOKUP(A25,ffbbudgettwofive,18,FALSE) -> 106
A26: 17 | B26: =VLOOKUP(A26,coupe,3,FALSE) -> 2011 | C26: =VLOOKUP(A26,DARSO,2,FALSE) -> 45.7 | D26: =VLOOKUP(A26,coupe,4,FALSE) -> 1005 | E26: =VLOOKUP(A26,year2022to23,311,FALSE) -> 797.25 | F26: =VLOOKUP(A26,budget2024,19,FALSE) -> 1005 | G26: =VLOOKUP(A26,year2022to23,249,FALSE) -> 814.55 | H26: =E26-G26 -> -17.3 | I26: =E26/C26 -> 17.445295 | J26: =G26/C26 -> 17.823851 | Z26: =VLOOKUP(A26,ffbbudgettwofive,7,FALSE) -> 50.25 | AA26: =VLOOKUP(A26,ffbbudgettwofive,8,FALSE) -> 40.2 | AB26: =VLOOKUP(A26,ffbbudgettwofive,9,FALSE) -> 70.35 | AC26: =VLOOKUP(A26,ffbbudgettwofive,10,FALSE) -> 70.35 | AD26: =VLOOKUP(A26,ffbbudgettwofive,11,FALSE) -> 70.35 | AE26: =VLOOKUP(A26,ffbbudgettwofive,12,FALSE) -> 70.35 | AF26: =VLOOKUP(A26,ffbbudgettwofive,13,FALSE) -> 80 | AG26: =VLOOKUP(A26,ffbbudgettwofive,14,FALSE) -> 101 | AH26: =VLOOKUP(A26,ffbbudgettwofive,15,FALSE) -> 101 | AI26: =VLOOKUP(A26,ffbbudgettwofive,16,FALSE) -> 141 | AJ26: =VLOOKUP(A26,ffbbudgettwofive,17,FALSE) -> 111 | AK26: =VLOOKUP(A26,ffbbudgettwofive,18,FALSE) -> 101
A27: 18 | B27: =VLOOKUP(A27,coupe,3,FALSE) -> 2011 | C27: =VLOOKUP(A27,NURAZANI,2,FALSE) -> 40.8 | D27: =VLOOKUP(A27,coupe,4,FALSE) -> 898 | E27: =VLOOKUP(A27,year2022to23,311,FALSE) -> 800.71 | F27: =VLOOKUP(A27,budget2024,19,FALSE) -> 898 | G27: =VLOOKUP(A27,year2022to23,249,FALSE) -> 737.08 | H27: =E27-G27 -> 63.63 | I27: =E27/C27 -> 19.625245 | J27: =G27/C27 -> 18.065686 | Z27: =VLOOKUP(A27,ffbbudgettwofive,7,FALSE) -> 44.9 | AA27: =VLOOKUP(A27,ffbbudgettwofive,8,FALSE) -> 35.92 | AB27: =VLOOKUP(A27,ffbbudgettwofive,9,FALSE) -> 62.86 | AC27: =VLOOKUP(A27,ffbbudgettwofive,10,FALSE) -> 62.86 | AD27: =VLOOKUP(A27,ffbbudgettwofive,11,FALSE) -> 62.86 | AE27: =VLOOKUP(A27,ffbbudgettwofive,12,FALSE) -> 62.86 | AF27: =VLOOKUP(A27,ffbbudgettwofive,13,FALSE) -> 72 | AG27: =VLOOKUP(A27,ffbbudgettwofive,14,FALSE) -> 90 | AH27: =VLOOKUP(A27,ffbbudgettwofive,15,FALSE) -> 90 | AI27: =VLOOKUP(A27,ffbbudgettwofive,16,FALSE) -> 126 | AJ27: =VLOOKUP(A27,ffbbudgettwofive,17,FALSE) -> 99 | AK27: =VLOOKUP(A27,ffbbudgettwofive,18,FALSE) -> 90
B29: =B30 -> 2012 | C29: =SUM(C30:C34) -> 281.9 | D29: =SUM(D30:D34) -> 5931 | E29: =SUM(E30:E34) -> 4872.33 | F29: =SUM(F30:F34) -> 5931 | G29: =SUM(G30:G34) -> 4448.03 | H29: =E29-G29 -> 424.3 | I29: =E29/C29 -> 17.283895 | J29: =G29/C29 -> 15.778751 | Z29: Jan | AA29: Feb | AB29: Mar | AC29: Apr | AD29: May | AE29: Jun | AF29: Jul | AG29: Aug | AH29: Sep | AI29: Oct | AJ29: Nov | AK29: Dec
A30: 19 | B30: =VLOOKUP(A30,coupe,3,FALSE) -> 2012 | C30: =VLOOKUP(A30,DARSO,2,FALSE) -> 50.62 | D30: =VLOOKUP(A30,coupe,4,FALSE) -> 1063 | E30: =VLOOKUP(A30,year2022to23,311,FALSE) -> 866 | F30: =VLOOKUP(A30,budget2024,19,FALSE) -> 1063 | G30: =VLOOKUP(A30,year2022to23,249,FALSE) -> 745.81 | H30: =E30-G30 -> 120.19 | I30: =E30/C30 -> 17.107863 | J30: =G30/C30 -> 14.733505 | Z30: =VLOOKUP(A30,ffbbudgettwofive,7,FALSE) -> 53.15 | AA30: =VLOOKUP(A30,ffbbudgettwofive,8,FALSE) -> 42.52 | AB30: =VLOOKUP(A30,ffbbudgettwofive,9,FALSE) -> 74.41 | AC30: =VLOOKUP(A30,ffbbudgettwofive,10,FALSE) -> 74.41 | AD30: =VLOOKUP(A30,ffbbudgettwofive,11,FALSE) -> 74.41 | AE30: =VLOOKUP(A30,ffbbudgettwofive,12,FALSE) -> 74.41 | AF30: =VLOOKUP(A30,ffbbudgettwofive,13,FALSE) -> 85 | AG30: =VLOOKUP(A30,ffbbudgettwofive,14,FALSE) -> 106 | AH30: =VLOOKUP(A30,ffbbudgettwofive,15,FALSE) -> 106 | AI30: =VLOOKUP(A30,ffbbudgettwofive,16,FALSE) -> 149 | AJ30: =VLOOKUP(A30,ffbbudgettwofive,17,FALSE) -> 117 | AK30: =VLOOKUP(A30,ffbbudgettwofive,18,FALSE) -> 106
